Workbook

Sheet Supuestos
A1: ATP Pro: supuestos del modelo de costos (4 de septiembre de 2026)
A2: Celdas azules con fondo amarillo = editables. Todo lo demás es fórmula. Fuentes en la hoja Fuentes.
A3: Cifras en MXN salvo que la etiqueta diga USD. Precios de tienda incluyen IVA (así se muestran al usuario).
A5: PRECIOS (MXN, IVA incluido)
A6: Pro mensual, precio A | B6: 449 | D6: Precio propuesto por Enrique
A7: Pro mensual, precio B | B7: 399 | D7: Alternativa que Enrique aceptaría
A8: Pro anual | B8: 3990 | D8: Incluye Diagnóstico ATP automático sin genética
A9: Founders (pago único, cupo 50) | B9: 8900 | D9: 1 hora con Enrique incluida
A10: IVA | B10: 0.16 | D10: LIVA art. 1
A11: Tipo de cambio MXN por USD (FIX Banxico 3 sep 2026) | B11: 16.956 | D11: DOF 4 sep 2026. El proxy usa 18.75 como techo interno; aquí se usa el FIX real
A12: COMISIONES DE CANAL
A13: Apple App Store, Small Business Program (sobre precio sin IVA) | B13: 0.15 | D13: Menos de 1M USD/año. Con RFC cargado, Apple te deposita el IVA de la venta y tú lo remites al SAT (igual que Google); sin RFC, Apple lo remite. Apple puede retener ISR e IVA: son anticipos, no costo
A14: Google Play, suscripciones (sobre precio sin IVA) | B14: 0.15 | D14: 15% en suscripciones sin importar umbral. IVA de la venta lo remites tú; Google cobra IVA sobre su comisión (acreditable)
A15: Stripe tarjeta nacional, porcentaje | B15: 0.036 | D15: Sobre el monto cobrado (con IVA). Más IVA sobre la comisión (acreditable)
A16: Stripe tarjeta nacional, fijo por cargo (MXN) | B16: 3 | D16: Más IVA (acreditable)
A17: Stripe Billing (sobre volumen) | B17: 0.007 | D17: Solo si usas Stripe Billing para suscripciones web
A18: RevenueCat, porcentaje del MTR | B18: 0.01 | D18: Gratis hasta 2,500 USD de MTR mensual; 1% después. MTR se mide antes de comisión de tienda
A19: RevenueCat, umbral gratis (USD MTR/mes) | B19: 2500 | D19: Se cobra 1% sobre todo el MTR al cruzar el umbral (conservador; RevenueCat podría cobrar solo sobre el excedente)
A20: IVA de comisiones acreditable (1 = sí, 0 = no) | B20: 1 | D20: Persona física con RFC acredita el IVA que Apple, Google y Stripe cobran sobre su comisión. Si el contador dice que no, pon 0: cuesta unos 8 MXN por suscriptor
A21: COSTO VARIABLE POR SUSCRIPTOR PRO (USD/mes)
A22: ARGOS (LLM) usuario ligero | B22: 0.8 | D22: Medido: usuarios pro/premium con 20 a 30 llamadas al mes cuestan 0.5 a 1.0 USD (argos_logs jun a sep 2026)
A23: ARGOS (LLM) usuario promedio | B23: 2.4 | D23: Medición que calibró el proxy: 2.4 USD/mes = 45 MXN (comentario en argos-proxy/index.ts). Tester más intenso en agosto: 1.6 USD
A24: ARGOS (LLM) usuario intenso | B24: 8 | D24: 136 MXN al FIX de hoy (el aviso del proxy son 150 MXN a 18.75). Un profesional que usa ARGOS diario llega aquí
A25: Porcentaje de suscriptores intensos | B25: 0.1 | D25: Cola de uso. Escenarios usa el promedio ponderado (fila siguiente); Unidad muestra los tres casos por separado
A26: ARGOS ponderado (fórmula) | B26: =$B$23*(1-$B$25)+$B$24*$B$25 -> 2.96 | D26: Promedio × (1 − intensos) + intenso × intensos
A27: Lectura de laboratorios (Sonnet 4.6 con PDF), por estudio | B27: 0.1 | D27: Estimado: PDF de 6 páginas ~12k tokens de entrada + 3k de salida a 3/15 USD por M = 0.08; se redondea a 0.10. PENDIENTE medir con lab-parser-worker
A28: Estudios subidos por suscriptor Pro al mes | B28: 0.5 | D28: Un estudio cada 2 meses en promedio; laboratorios reales se repiten cada 3 a 6 meses
A29: Voz ARGOS (ElevenLabs Flash, 0.05 USD por 1k caracteres) | B29: 0.3 | D29: 6,000 caracteres al mes. Medido en agosto: 3 llamadas = 0.017 USD. Sube si la voz se vuelve central
A30: Diagnóstico ATP automático (Sonnet 5), por generación | B30: 0.2 | D30: ~40k tokens entrada + 8k salida. Solo plan anual, 1 vez al año
A31: COSTO DE USUARIOS GRATIS (USD)
A32: Alta de usuario gratis (1 estudio + 3 mensajes ARGOS), único | B32: 0.1 | D32: Tope 0.20 si el 100% sube estudio y manda 3 mensajes; en freemium menos del 30% completa el primer paso pesado
A33: Altas gratis nuevas al mes (como % de la base gratis) | B33: 0.2 | D33: 3 altas por suscriptor Pro al mes con ratio 15; alto en estado estable, bajo en lanzamiento
A34: Usuario gratis activo, mensual | B34: 0.03 | D34: Casi todo idle (Supabase, egress, push). NO incluye EAS por MAU, que va aparte. Sube a 0.15 si el free recibe mensajes ARGOS recurrentes
A35: Usuarios gratis por cada suscriptor Pro | B35: 20 | D35: Conversión free a pago 5%. Base razonable para salud freemium en MX: 4% (25 gratis); optimista 6% (15); pesimista 2% (50)
A36: COSTOS FIJOS MENSUALES (USD)
A37: Supabase Pro | B37: 25 | D37: Incluye Micro compute con el crédito de 10 USD; 100k MAU; 8 GB DB
A38: Sentry | B38: 0 | D38: Developer gratis hasta 5k errores; Team 26 USD cuando haga falta
A39: PostHog | B39: 0 | D39: 1M eventos gratis al mes
A40: Resend | B40: 0 | D40: 3,000 correos gratis al mes con tope de 100 al día; Pro 20 USD cuando el tope diario estorbe
A41: Expo EAS, plan Starter (USD/mes) al pasar de 1,000 MAU | B41: 19 | D41: Free hasta 1,000 MAU en EAS Update; Starter incluye 3,000 MAU; después 0.005 USD por MAU. Escenarios lo aplica por escalón
...

Sheet Unidad
A1: Economía por suscriptor Pro al mes (MXN)
A2: Lo que queda de cada suscripción después de IVA, comisión del canal, RevenueCat y costo de IA. Antes de ISR (impuesto sobre la utilidad, no costo).
A4: Concepto | B4: 449 App Store | C4: 449 Google Play | D4: 449 Stripe web | E4: 399 App Store | F4: 399 Google Play | G4: 399 Stripe web | H4: Anual 3,990 App Store (por mes) | I4: Anual 3,990 Stripe (por mes)
A5: Precio cobrado al usuario (con IVA) | B5: =Supuestos!$B$6 -> 449 | C5: =Supuestos!$B$6 -> 449 | D5: =Supuestos!$B$6 -> 449 | E5: =Supuestos!$B$7 -> 399 | F5: =Supuestos!$B$7 -> 399 | G5: =Supuestos!$B$7 -> 399 | H5: =Supuestos!$B$8/12 -> 332.5 | I5: =Supuestos!$B$8/12 -> 332.5
A6: IVA (16%) que se remite al SAT | B6: =B5-B5/(1+Supuestos!$B$10) -> 61.931034 | C6: =C5-C5/(1+Supuestos!$B$10) -> 61.931034 | D6: =D5-D5/(1+Supuestos!$B$10) -> 61.931034 | E6: =E5-E5/(1+Supuestos!$B$10) -> 55.034483 | F6: =F5-F5/(1+Supuestos!$B$10) -> 55.034483 | G6: =G5-G5/(1+Supuestos!$B$10) -> 55.034483 | H6: =H5-H5/(1+Supuestos!$B$10) -> 45.862069 | I6: =I5-I5/(1+Supuestos!$B$10) -> 45.862069
A7: Ingreso sin IVA | B7: =B5-B6 -> 387.06897 | C7: =C5-C6 -> 387.06897 | D7: =D5-D6 -> 387.06897 | E7: =E5-E6 -> 343.96552 | F7: =F5-F6 -> 343.96552 | G7: =G5-G6 -> 343.96552 | H7: =H5-H6 -> 286.63793 | I7: =I5-I6 -> 286.63793
A8: Comisión del canal | B8: =B7*Supuestos!$B$13 -> 58.060345 | C8: =C7*Supuestos!$B$14 -> 58.060345 | D8: =D5*Supuestos!$B$15 -> 16.164 | E8: =E7*Supuestos!$B$13 -> 51.594828 | F8: =F7*Supuestos!$B$14 -> 51.594828 | G8: =G5*Supuestos!$B$15 -> 14.364 | H8: =H7*Supuestos!$B$13 -> 42.99569 | I8: =I5*Supuestos!$B$15 -> 11.97
A9: Stripe: fijo por cargo | B9: 0 | C9: 0 | D9: =Supuestos!$B$16 -> 3 | E9: 0 | F9: 0 | G9: =Supuestos!$B$16 -> 3 | H9: 0 | I9: =Supuestos!$B$16 -> 3
A10: Stripe Billing | B10: 0 | C10: 0 | D10: =D5*Supuestos!$B$17 -> 3.143 | E10: 0 | F10: 0 | G10: =G5*Supuestos!$B$17 -> 2.793 | H10: 0 | I10: =I5*Supuestos!$B$17 -> 2.3275
A11: RevenueCat (1% del MTR, cuando aplica) | B11: =B5*Supuestos!$B$18 -> 4.49 | C11: =C5*Supuestos!$B$18 -> 4.49 | D11: 0 | E11: =E5*Supuestos!$B$18 -> 3.99 | F11: =F5*Supuestos!$B$18 -> 3.99 | G11: 0 | H11: =H5*Supuestos!$B$18 -> 3.325 | I11: 0
A12: IVA sobre comisiones si NO se acredita (Supuestos) | B12: =(1-Supuestos!$B$20)*Supuestos!$B$10*(B8+B9+B10) -> 0 | C12: =(1-Supuestos!$B$20)*Supuestos!$B$10*(C8+C9+C10) -> 0 | D12: =(1-Supuestos!$B$20)*Supuestos!$B$10*(D8+D9+D10) -> 0 | E12: =(1-Supuestos!$B$20)*Supuestos!$B$10*(E8+E9+E10) -> 0 | F12: =(1-Supuestos!$B$20)*Supuestos!$B$10*(F8+F9+F10) -> 0 | G12: =(1-Supuestos!$B$20)*Supuestos!$B$10*(G8+G9+G10) -> 0 | H12: =(1-Supuestos!$B$20)*Supuestos!$B$10*(H8+H9+H10) -> 0 | I12: =(1-Supuestos!$B$20)*Supuestos!$B$10*(I8+I9+I10) -> 0
A13: Neto que te deposita el canal | B13: =B7-B8-B9-B10-B11-B12 -> 324.51862 | C13: =C7-C8-C9-C10-C11-C12 -> 324.51862 | D13: =D7-D8-D9-D10-D11-D12 -> 364.76197 | E13: =E7-E8-E9-E10-E11-E12 -> 288.38069 | F13: =F7-F8-F9-F10-F11-F12 -> 288.38069 | G13: =G7-G8-G9-G10-G11-G12 -> 323.80852 | H13: =H7-H8-H9-H10-H11-H12 -> 240.31724 | I13: =I7-I8-I9-I10-I11-I12 -> 269.34043
A14: ARGOS LLM, usuario promedio (MXN) | B14: =Supuestos!$B$23*Supuestos!$B$11 -> 40.6944 | C14: =Supuestos!$B$23*Supuestos!$B$11 -> 40.6944 | D14: =Supuestos!$B$23*Supuestos!$B$11 -> 40.6944 | E14: =Supuestos!$B$23*Supuestos!$B$11 -> 40.6944 | F14: =Supuestos!$B$23*Supuestos!$B$11 -> 40.6944 | G14: =Supuestos!$B$23*Supuestos!$B$11 -> 40.6944 | H14: =Supuestos!$B$23*Supuestos!$B$11 -> 40.6944 | I14: =Supuestos!$B$23*Supuestos!$B$11 -> 40.6944
A15: Lectura de laboratorios (MXN) | B15: =Supuestos!$B$27*Supuestos!$B$28*Supuestos!$B$11 -> 0.8478 | C15: =Supuestos!$B$27*Supuestos!$B$28*Supuestos!$B$11 -> 0.8478 | D15: =Supuestos!$B$27*Supuestos!$B$28*Supuestos!$B$11 -> 0.8478 | E15: =Supuestos!$B$27*Supuestos!$B$28*Supuestos!$B$11 -> 0.8478 | F15: =Supuestos!$B$27*Supuestos!$B$28*Supuestos!$B$11 -> 0.8478 | G15: =Supuestos!$B$27*Supuestos!$B$28*Supuestos!$B$11 -> 0.8478 | H15: =Supuestos!$B$27*Supuestos!$B$28*Supuestos!$B$11 -> 0.8478 | I15: =Supuestos!$B$27*Supuestos!$B$28*Supuestos!$B$11 -> 0.8478
A16: Voz (MXN) | B16: =Supuestos!$B$29*Supuestos!$B$11 -> 5.0868 | C16: =Supuestos!$B$29*Supuestos!$B$11 -> 5.0868 | D16: =Supuestos!$B$29*Supuestos!$B$11 -> 5.0868 | E16: =Supuestos!$B$29*Supuestos!$B$11 -> 5.0868 | F16: =Supuestos!$B$29*Supuestos!$B$11 -> 5.0868 | G16: =Supuestos!$B$29*Supuestos!$B$11 -> 5.0868 | H16: =Supuestos!$B$29*Supuestos!$B$11 -> 5.0868 | I16: =Supuestos!$B$29*Supuestos!$B$11 -> 5.0868
A17: Diagnóstico ATP automático (solo anual, prorrateado) | B17: 0 | C17: 0 | D17: 0 | E17: 0 | F17: 0 | G17: 0 | H17: =Supuestos!$B$30*Supuestos!$B$11/12 -> 0.2826 | I17: =Supuestos!$B$30*Supuestos!$B$11/12 -> 0.2826
A18: Costo variable total, usuario promedio | B18: =SUM(B14:B17) -> 46.629 | C18: =SUM(C14:C17) -> 46.629 | D18: =SUM(D14:D17) -> 46.629 | E18: =SUM(E14:E17) -> 46.629 | F18: =SUM(F14:F17) -> 46.629 | G18: =SUM(G14:G17) -> 46.629 | H18: =SUM(H14:H17) -> 46.9116 | I18: =SUM(I14:I17) -> 46.9116
A19: CONTRIBUCIÓN por suscriptor, usuario promedio | B19: =B13-B18 -> 277.88962 | C19: =C13-C18 -> 277.88962 | D19: =D13-D18 -> 318.13297 | E19: =E13-E18 -> 241.75169 | F19: =F13-F18 -> 241.75169 | G19: =G13-G18 -> 277.17952 | H19: =H13-H18 -> 193.40564 | I19: =I13-I18 -> 222.42883
A20: Margen sobre ingreso sin IVA | B20: =IF(B7=0,0,B19/B7) -> 0.7179331 | C20: =IF(C7=0,0,C19/C7) -> 0.7179331 | D20: =IF(D7=0,0,D19/D7) -> 0.82190254 | E20: =IF(E7=0,0,E19/E7) -> 0.70283699 | F20: =IF(F7=0,0,F19/F7) -> 0.70283699 | G20: =IF(G7=0,0,G19/G7) -> 0.80583519 | H20: =IF(H7=0,0,H19/H7) -> 0.67473848 | I20: =IF(I7=0,0,I19/I7) -> 0.77599231
A21: Contribución si el usuario es ligero | B21: =B19+(Supuestos!$B$23-Supuestos!$B$22)*Supuestos!$B$11 -> 305.01922 | C21: =C19+(Supuestos!$B$23-Supuestos!$B$22)*Supuestos!$B$11 -> 305.01922 | D21: =D19+(Supuestos!$B$23-Supuestos!$B$22)*Supuestos!$B$11 -> 345.26257 | E21: =E19+(Supuestos!$B$23-Supuestos!$B$22)*Supuestos!$B$11 -> 268.88129 | F21: =F19+(Supuestos!$B$23-Supuestos!$B$22)*Supuestos!$B$11 -> 268.88129 | G21: =G19+(Supuestos!$B$23-Supuestos!$B$22)*Supuestos!$B$11 -> 304.30912 | H21: =H19+(Supuestos!$B$23-Supuestos!$B$22)*Supuestos!$B$11 -> 220.53524 | I21: =I19+(Supuestos!$B$23-Supuestos!$B$22)*Supuestos!$B$11 -> 249.55843
A22: Contribución si el usuario es intenso (136 MXN de IA) | B22: =B19-(Supuestos!$B$24-Supuestos!$B$23)*Supuestos!$B$11 -> 182.93602 | C22: =C19-(Supuestos!$B$24-Supuestos!$B$23)*Supuestos!$B$11 -> 182.93602 | D22: =D19-(Supuestos!$B$24-Supuestos!$B$23)*Supuestos!$B$11 -> 223.17937 | E22: =E19-(Supuestos!$B$24-Supuestos!$B$23)*Supuestos!$B$11 -> 146.79809 | F22: =F19-(Supuestos!$B$24-Supuestos!$B$23)*Supuestos!$B$11 -> 146.79809 | G22: =G19-(Supuestos!$B$24-Supuestos!$B$23)*Supuestos!$B$11 -> 182.22592 | H22: =H19-(Supuestos!$B$24-Supuestos!$B$23)*Supuestos!$B$11 -> 98.452041 | I22: =I19-(Supuestos!$B$24-Supuestos!$B$23)*Supuestos!$B$11 -> 127.47523
A24: Punto de quiebre: gasto de IA (USD/mes) que deja contribución en cero | B24: =(B13-B15-B16-B17)/Supuestos!$B$11 -> 18.788867 | C24: =(C13-C15-C16-C17)/Supuestos!$B$11 -> 18.788867 | D24: =(D13-D15-D16-D17)/Supuestos!$B$11 -> 21.162265 | E24: =(E13-E15-E16-E17)/Supuestos!$B$11 -> 16.65759 | F24: =(F13-F15-F16-F17)/Supuestos!$B$11 -> 16.65759 | G24: =(G13-G15-G16-G17)/Supuestos!$B$11 -> 18.746987 | H24: =(H13-H15-H16-H17)/Supuestos!$B$11 -> 13.806325 | I24: =(I13-I15-I16-I17)/Supuestos!$B$11 -> 15.518001
A26: Lectura: la diferencia entre 449 y 399 es de 36 a 41 MXN de contribución por suscriptor al mes. La diferencia entre cobrar en tienda o en web es parecida (35 a 40 MXN). Bajar el precio y no empujar el pago web es pagar dos veces.
A28: Nota RevenueCat: el 1% aplica solo cuando el MTR mensual de tiendas pasa de 2,500 USD (unos 118 suscriptores a 449 con 80% en tiendas; 94 si todos pagaran en tienda). Aquí se carga siempre para no subestimar. En web se asume Stripe directo sin RevenueCat.

Sheet Escenarios
A1: Escenarios mensuales por número de suscriptores Pro (precio A = 449, mix de canal de Supuestos)
A2: Resultado antes de ISR. Founders y Elite no están aquí: son ingresos aparte (ver hoja Founders).
A4: Suscriptores Pro mensuales | B4: 25 | C4: 50 | D4: 100 | E4: 250 | F4: 500 | G4: 1000
A5: Precio mensual usado (edítalo: 449 o 399) | B5: 449 | D5: Todas las filas de abajo y el punto de equilibrio siguen a este precio
A6: Contador (MXN/mes) | B6: 2500 | D6: Estimado, no verificado (1,500 a 3,500). Plataformas tecnológicas + Stripe hacen la contabilidad más laboriosa
A7: Meta de ingreso personal de Enrique (MXN/mes, antes de ISR) | B7: 40000 | D7: Captura tu número real; el punto de equilibrio de abajo lo usa
A9: Cobro bruto a usuarios (con IVA) | B9: =B$4*$B$5 -> 11225 | C9: =C$4*$B$5 -> 22450 | D9: =D$4*$B$5 -> 44900 | E9: =E$4*$B$5 -> 112250 | F9: =F$4*$B$5 -> 224500 | G9: =G$4*$B$5 -> 449000
A10: IVA remitido | B10: =B9-B9/(1+Supuestos!$B$10) -> 1548.2759 | C10: =C9-C9/(1+Supuestos!$B$10) -> 3096.5517 | D10: =D9-D9/(1+Supuestos!$B$10) -> 6193.1034 | E10: =E9-E9/(1+Supuestos!$B$10) -> 15482.759 | F10: =F9-F9/(1+Supuestos!$B$10) -> 30965.517 | G10: =G9-G9/(1+Supuestos!$B$10) -> 61931.034
A11: Ingreso sin IVA | B11: =B9-B10 -> 9676.7241 | C11: =C9-C10 -> 19353.448 | D11: =D9-D10 -> 38706.897 | E11: =E9-E10 -> 96767.241 | F11: =F9-F10 -> 193534.48 | G11: =G9-G10 -> 387068.97
A12: Comisiones de canal (mix) | B12: =(B11*(Supuestos!$B$50*Supuestos!$B$13+Supuestos!$B$51*Supuestos!$B$14)+B$4*Supuestos!$B$52*($B$5*Supuestos!$B$15+Supuestos!$B$16+$B$5*Supuestos!$B$17))*(1+(1-Supuestos!$B$20)*Supuestos!$B$10) -> 1272.7419 | C12: =(C11*(Supuestos!$B$50*Supuestos!$B$13+Supuestos!$B$51*Supuestos!$B$14)+C$4*Supuestos!$B$52*($B$5*Supuestos!$B$15+Supuestos!$B$16+$B$5*Supuestos!$B$17))*(1+(1-Supuestos!$B$20)*Supuestos!$B$10) -> 2545.4838 | D12: =(D11*(Supuestos!$B$50*Supuestos!$B$13+Supuestos!$B$51*Supuestos!$B$14)+D$4*Supuestos!$B$52*($B$5*Supuestos!$B$15+Supuestos!$B$16+$B$5*Supuestos!$B$17))*(1+(1-Supuestos!$B$20)*Supuestos!$B$10) -> 5090.9676 | E12: =(E11*(Supuestos!$B$50*Supuestos!$B$13+Supuestos!$B$51*Supuestos!$B$14)+E$4*Supuestos!$B$52*($B$5*Supuestos!$B$15+Supuestos!$B$16+$B$5*Supuestos!$B$17))*(1+(1-Supuestos!$B$20)*Supuestos!$B$10) -> 12727.419 | F12: =(F11*(Supuestos!$B$50*Supuestos!$B$13+Supuestos!$B$51*Supuestos!$B$14)+F$4*Supuestos!$B$52*($B$5*Supuestos!$B$15+Supuestos!$B$16+$B$5*Supuestos!$B$17))*(1+(1-Supuestos!$B$20)*Supuestos!$B$10) -> 25454.838 | G12: =(G11*(Supuestos!$B$50*Supuestos!$B$13+Supuestos!$B$51*Supuestos!$B$14)+G$4*Supuestos!$B$52*($B$5*Supuestos!$B$15+Supuestos!$B$16+$B$5*Supuestos!$B$17))*(1+(1-Supuestos!$B$20)*Supuestos!$B$10) -> 50909.676
A13: RevenueCat (solo si MTR de tiendas > umbral) | B13: =IF(B9*(Supuestos!$B$50+Supuestos!$B$51)/Supuestos!$B$11>Supuestos!$B$19,B9*(Supuestos!$B$50+Supuestos!$B$51)*Supuestos!$B$18,0) -> 0 | C13: =IF(C9*(Supuestos!$B$50+Supuestos!$B$51)/Supuestos!$B$11>Supuestos!$B$19,C9*(Supuestos!$B$50+Supuestos!$B$51)*Supuestos!$B$18,0) -> 0 | D13: =IF(D9*(Supuestos!$B$50+Supuestos!$B$51)/Supuestos!$B$11>Supuestos!$B$19,D9*(Supuestos!$B$50+Supuestos!$B$51)*Supuestos!$B$18,0) -> 0 | E13: =IF(E9*(Supuestos!$B$50+Supuestos!$B$51)/Supuestos!$B$11>Supuestos!$B$19,E9*(Supuestos!$B$50+Supuestos!$B$51)*Supuestos!$B$18,0) -> 898 | F13: =IF(F9*(Supuestos!$B$50+Supuestos!$B$51)/Supuestos!$B$11>Supuestos!$B$19,F9*(Supuestos!$B$50+Supuestos!$B$51)*Supuestos!$B$18,0) -> 1796 | G13: =IF(G9*(Supuestos!$B$50+Supuestos!$B$51)/Supuestos!$B$11>Supuestos!$B$19,G9*(Supuestos!$B$50+Supuestos!$B$51)*Supuestos!$B$18,0) -> 3592
A14: Neto depositado | B14: =B11-B12-B13 -> 8403.9822 | C14: =C11-C12-C13 -> 16807.964 | D14: =D11-D12-D13 -> 33615.929 | E14: =E11-E12-E13 -> 83141.822 | F14: =F11-F12-F13 -> 166283.64 | G14: =G11-G12-G13 -> 332567.29
A15: IA: ARGOS ponderado (con cola de intensos) + laboratorios + voz | B15: =B$4*(Supuestos!$B$26+Supuestos!$B$27*Supuestos!$B$28+Supuestos!$B$29)*Supuestos!$B$11 -> 1403.109 | C15: =C$4*(Supuestos!$B$26+Supuestos!$B$27*Supuestos!$B$28+Supuestos!$B$29)*Supuestos!$B$11 -> 2806.218 | D15: =D$4*(Supuestos!$B$26+Supuestos!$B$27*Supuestos!$B$28+Supuestos!$B$29)*Supuestos!$B$11 -> 5612.436 | E15: =E$4*(Supuestos!$B$26+Supuestos!$B$27*Supuestos!$B$28+Supuestos!$B$29)*Supuestos!$B$11 -> 14031.09 | F15: =F$4*(Supuestos!$B$26+Supuestos!$B$27*Supuestos!$B$28+Supuestos!$B$29)*Supuestos!$B$11 -> 28062.18 | G15: =G$4*(Supuestos!$B$26+Supuestos!$B$27*Supuestos!$B$28+Supuestos!$B$29)*Supuestos!$B$11 -> 56124.36
A16: Usuarios gratis: altas del mes (% de Supuestos) | B16: =B$4*Supuestos!$B$35*Supuestos!$B$33*Supuestos!$B$32*Supuestos!$B$11 -> 169.56 | C16: =C$4*Supuestos!$B$35*Supuestos!$B$33*Supuestos!$B$32*Supuestos!$B$11 -> 339.12 | D16: =D$4*Supuestos!$B$35*Supuestos!$B$33*Supuestos!$B$32*Supuestos!$B$11 -> 678.24 | E16: =E$4*Supuestos!$B$35*Supuestos!$B$33*Supuestos!$B$32*Supuestos!$B$11 -> 1695.6 | F16: =F$4*Supuestos!$B$35*Supuestos!$B$33*Supuestos!$B$32*Supuestos!$B$11 -> 3391.2 | G16: =G$4*Supuestos!$B$35*Supuestos!$B$33*Supuestos!$B$32*Supuestos!$B$11 -> 6782.4
A17: Usuarios gratis: mensual | B17: =B$4*Supuestos!$B$35*Supuestos!$B$34*Supuestos!$B$11 -> 254.34 | C17: =C$4*Supuestos!$B$35*Supuestos!$B$34*Supuestos!$B$11 -> 508.68 | D17: =D$4*Supuestos!$B$35*Supuestos!$B$34*Supuestos!$B$11 -> 1017.36 | E17: =E$4*Supuestos!$B$35*Supuestos!$B$34*Supuestos!$B$11 -> 2543.4 | F17: =F$4*Supuestos!$B$35*Supuestos!$B$34*Supuestos!$B$11 -> 5086.8 | G17: =G$4*Supuestos!$B$35*Supuestos!$B$34*Supuestos!$B$11 -> 10173.6
A18: Costos fijos base + escalones Resend y Sentry (USD a MXN) | B18: =(Supuestos!$B$37+Supuestos!$B$38+Supuestos!$B$39+Supuestos!$B$40+Supuestos!$B$47+Supuestos!$B$48+IF(B$4*(1+Supuestos!$B$35)>1500,Supuestos!$B$45,0)+IF(B$4*(1+Supuestos!$B$35)>2500,Supuestos!$B$46,0))*Supuestos!$B$11 -> 733.347 | C18: =(Supuestos!$B$37+Supuestos!$B$38+Supuestos!$B$39+Supuestos!$B$40+Supuestos!$B$47+Supuestos!$B$48+IF(C$4*(1+Supuestos!$B$35)>1500,Supuestos!$B$45,0)+IF(C$4*(1+Supuestos!$B$35)>2500,Supuestos!$B$46,0))*Supuestos!$B$11 -> 733.347 | D18: =(Supuestos!$B$37+Supuestos!$B$38+Supuestos!$B$39+Supuestos!$B$40+Supuestos!$B$47+Supuestos!$B$48+IF(D$4*(1+Supuestos!$B$35)>1500,Supuestos!$B$45,0)+IF(D$4*(1+Supuestos!$B$35)>2500,Supuestos!$B$46,0))*Supuestos!$B$11 -> 1072.467 | E18: =(Supuestos!$B$37+Supuestos!$B$38+Supuestos!$B$39+Supuestos!$B$40+Supuestos!$B$47+Supuestos!$B$48+IF(E$4*(1+Supuestos!$B$35)>1500,Supuestos!$B$45,0)+IF(E$4*(1+Supuestos!$B$35)>2500,Supuestos!$B$46,0))*Supuestos!$B$11 -> 1513.323 | F18: =(Supuestos!$B$37+Supuestos!$B$38+Supuestos!$B$39+Supuestos!$B$40+Supuestos!$B$47+Supuestos!$B$48+IF(F$4*(1+Supuestos!$B$35)>1500,Supuestos!$B$45,0)+IF(F$4*(1+Supuestos!$B$35)>2500,Supuestos!$B$46,0))*Supuestos!$B$11 -> 1513.323 | G18: =(Supuestos!$B$37+Supuestos!$B$38+Supuestos!$B$39+Supuestos!$B$40+Supuestos!$B$47+Supuestos!$B$48+IF(G$4*(1+Supuestos!$B$35)>1500,Supuestos!$B$45,0)+IF(G$4*(1+Supuestos!$B$35)>2500,Supuestos!$B$46,0))*Supuestos!$B$11 -> 1513.323
A19: Expo EAS por escalón (Starter al pasar de 1,000 MAU, luego por MAU) | B19: =IF(B$4*(1+Supuestos!$B$35)>Supuestos!$B$42,Supuestos!$B$41+MAX(0,B$4*(1+Supuestos!$B$35)-Supuestos!$B$43)*Supuestos!$B$44,0)*Supuestos!$B$11 -> 0 | C19: =IF(C$4*(1+Supuestos!$B$35)>Supuestos!$B$42,Supuestos!$B$41+MAX(0,C$4*(1+Supuestos!$B$35)-Supuestos!$B$43)*Supuestos!$B$44,0)*Supuestos!$B$11 -> 322.164 | D19: =IF(D$4*(1+Supuestos!$B$35)>Supuestos!$B$42,Supuestos!$B$41+MAX(0,D$4*(1+Supuestos!$B$35)-Supuestos!$B$43)*Supuestos!$B$44,0)*Supuestos!$B$11 -> 322.164 | E19: =IF(E$4*(1+Supuestos!$B$35)>Supuestos!$B$42,Supuestos!$B$41+MAX(0,E$4*(1+Supuestos!$B$35)-Supuestos!$B$43)*Supuestos!$B$44,0)*Supuestos!$B$11 -> 512.919 | F19: =IF(F$4*(1+Supuestos!$B$35)>Supuestos!$B$42,Supuestos!$B$41+MAX(0,F$4*(1+Supuestos!$B$35)-Supuestos!$B$43)*Supuestos!$B$44,0)*Supuestos!$B$11 -> 958.014 | G19: =IF(G$4*(1+Supuestos!$B$35)>Supuestos!$B$42,Supuestos!$B$41+MAX(0,G$4*(1+Supuestos!$B$35)-Supuestos!$B$43)*Supuestos!$B$44,0)*Supuestos!$B$11 -> 1848.204
A20: Contador | B20: =$B$6 -> 2500 | C20: =$B$6 -> 2500 | D20: =$B$6 -> 2500 | E20: =$B$6 -> 2500 | F20: =$B$6 -> 2500 | G20: =$B$6 -> 2500
A21: RESULTADO ANTES DE ISR | B21: =B14-SUM(B15:B20) -> 3343.6262 | C21: =C14-SUM(C15:C20) -> 9598.4355 | D21: =D14-SUM(D15:D20) -> 22413.262 | E21: =E14-SUM(E15:E20) -> 60345.49 | F21: =F14-SUM(F15:F20) -> 124772.13 | G21: =G14-SUM(G15:G20) -> 253625.4
A22: Margen sobre ingreso sin IVA | B22: =IF(B11=0,0,B21/B11) -> 0.34553287 | C22: =IF(C11=0,0,C21/C11) -> 0.4959548 | D22: =IF(D11=0,0,D21/D11) -> 0.57905087 | E22: =IF(E11=0,0,E21/E11) -> 0.62361487 | F22: =IF(F11=0,0,F21/F11) -> 0.64470231 | G22: =IF(G11=0,0,G21/G11) -> 0.65524603
A23: Costo de IA como % del neto depositado | B23: =IF(B14=0,0,B15/B14) -> 0.16695764 | C23: =IF(C14=0,0,C15/C14) -> 0.16695764 | D23: =IF(D14=0,0,D15/D14) -> 0.16695764 | E23: =IF(E14=0,0,E15/E14) -> 0.16876091 | F23: =IF(F14=0,0,F15/F14) -> 0.16876091 | G23: =IF(G14=0,0,G15/G14) -> 0.16876091
A24: Falta o sobra respecto a la meta personal | B24: =B21-$B$7 -> -36656.374 | C24: =C21-$B$7 -> -30401.565 | D24: =D21-$B$7 -> -17586.738 | E24: =E21-$B$7 -> 20345.49 | F24: =F21-$B$7 -> 84772.128 | G24: =G21-$B$7 -> 213625.4
A27: PUNTO DE EQUILIBRIO (aproximación: contribución por suscriptor con RevenueCat siempre cargado y EAS Starter como fijo)
A28: Contribución por suscriptor con el mix de canal, al precio de B5 (MXN) | B28: =($B$5/(1+Supuestos!$B$10)*(1-Supuestos!$B$50*Supuestos!$B$13-Supuestos!$B$51*Supuestos!$B$14)-Supuestos!$B$52*($B$5*Supuestos!$B$15+Supuestos!$B$16+$B$5*Supuestos!$B$17)-(Supuestos!$B$50+Supuestos!$B$51)*$B$5*Supuestos!$B$18)-(1-Supuestos!$B$20)*Supuestos!$B$10*($B$5/(1+Supuestos!$B$10)*(Supuestos!$B$50*Supuestos!$B$13+Supuestos!$B$51*Supuestos!$B$14)+Supuestos!$B$52*($B$5*Supuestos!$B$15+Supuestos!$B$16+$B$5*Supuestos!$B$17))-(Supuestos!$B$26+Supuestos!$B$27*Supuestos!$B$28+Supuestos!$B$29)*Supuestos!$B$11-(Supuestos!$B$35*Supuestos!$B$33*Supuestos!$B$32+Supuestos!$B$35*Supuestos!$B$34)*Supuestos!$B$11 -> 259.48693
A29: Fijos mensuales (infra base + EAS Starter + contador), MXN | B29: =(Supuestos!$B$37+Supuestos!$B$38+Supuestos!$B$39+Supuestos!$B$40+Supuestos!$B$47+Supuestos!$B$48+Supuestos!$B$41)*Supuestos!$B$11+$B$6 -> 3555.511
A30: Suscriptores para cubrir solo fijos y contador | B30: =ROUNDUP(B29/B28,0) -> 14
A31: Suscriptores para cubrir fijos, contador y la meta personal (B7) | B31: =ROUNDUP((B29+$B$7)/B28,0) -> 168
A32: Lo mismo si todos pagaran por web (Stripe) al precio de B5 | B32: =ROUNDUP((B29+$B$7)/(($B$5/(1+Supuestos!$B$10)-$B$5*Supuestos!$B$15-Supuestos!$B$16-$B$5*Supuestos!$B$17)-(1-Supuestos!$B$20)*Supuestos!$B$10*($B$5*Supuestos!$B$15+Supuestos!$B$16+$B$5*Supuestos!$B$17)-(Supuestos!$B$26+Supuestos!$B$27*Supuestos!$B$28+Supuestos!$B$29)*Supuestos!$B$11-(Supuestos!$B$35*Supuestos!$B$33*Supuestos!$B$32+Supuestos!$B$35*Supuestos!$B$34)*Supuestos!$B$11),0) -> 150
A33: Lo mismo al precio B (399) con el mix | B33: =ROUNDUP((B29+$B$7)/((Supuestos!$B$7/(1+Supuestos!$B$10)*(1-Supuestos!$B$50*Supuestos!$B$13-Supuestos!$B$51*Supuestos!$B$14)-Supuestos!$B$52*(Supuestos!$B$7*Supuestos!$B$15+Supuestos!$B$16+Supuestos!$B$7*Supuestos!$B$17)-(Supuestos!$B$50+Supuestos!$B$51)*Supuestos!$B$7*Supuestos!$B$18)-(1-Supuestos!$B$20)*Supuestos!$B$10*(Supuestos!$B$7/(1+Supuestos!$B$10)*(Supuestos!$B$50*Supuestos!$B$13+Supuestos!$B$51*Supuestos!$B$14)+Supuestos!$B$52*(Supuestos!$B$7*Supuestos!$B$15+Supuestos!$B$16+Supuestos!$B$7*Supuestos!$B$17))-(Supuestos!$B$26+Supuestos!$B$27*Supuestos!$B$28+Supuestos!$B$29)*Supuestos!$B$11-(Supuestos!$B$35*Supuestos!$B$33*Supuestos!$B$32+Supuestos!$B$35*Supuestos!$B$34)*Supuestos!$B$11),0) -> 196
A34: Lo mismo al precio B (399) todo por web | B34: =ROUNDUP((B29+$B$7)/((Supuestos!$B$7/(1+Supuestos!$B$10)-Supuestos!$B$7*Supuestos!$B$15-Supuestos!$B$16-Supuestos!$B$7*Supuestos!$B$17)-(1-Supuestos!$B$20)*Supuestos!$B$10*(Supuestos!$B$7*Supuestos!$B$15+Supuestos!$B$16+Supuestos!$B$7*Supuestos!$B$17)-(Supuestos!$B$26+Supuestos!$B$27*Supuestos!$B$28+Supuestos!$B$29)*Supuestos!$B$11-(Supuestos!$B$35*Supuestos!$B$33*Supuestos!$B$32+Supuestos!$B$35*Supuestos!$B$34)*Supuestos!$B$11),0) -> 174
A36: Nota: el equilibrio carga RevenueCat desde el primer suscriptor y EAS Starter como fijo; por eso sale 2 o 3 suscriptores más alto que la tabla de arriba en niveles bajos. Los escalones de Resend y Sentry (arriba de 1,500 y 2,500 usuarios totales) sí están en la tabla, no en el equilibrio. No incluye reembolsos ni pagos fallidos (2 a 5% en suscripciones) ni la hora con Enrique de Founders.

Sheet Founders
A1: Founders y anual: qué deja cada venta (MXN, antes de ISR)
A3: Founders 8,900 (pago único, cupo 50)
A4: Precio con IVA | B4: =Supuestos!$B$9 -> 8900
A5: Ingreso sin IVA | B5: =B4/(1+Supuestos!$B$10) -> 7672.4138
A6: Neto si se cobra por Stripe (web, un solo cargo) | B6: =B5-B4*Supuestos!$B$15-Supuestos!$B$16 -> 7349.0138 | C6: Founders conviene venderlo por web, nunca por tienda: la diferencia es de 916 MXN por venta
A7: Neto si se cobra por App Store (compra única, 15%) | B7: =B5*(1-Supuestos!$B$13)-B4*Supuestos!$B$18 -> 6432.5517
A8: Costo de IA de un Founder en 5 años (usuario promedio, 60 meses) | B8: =(Supuestos!$B$23+Supuestos!$B$27*Supuestos!$B$28+Supuestos!$B$29)*Supuestos!$B$11*60 -> 2797.74 | C8: Un Founder intenso agota el neto de 8,900 en unos 52 meses: a 5 años queda en negativo (B11). Por eso Founders necesita un límite de uso justo o definirse como 5 años, no vitalicio. La hora con Enrique no está costeada aquí
A9: Costo de IA si el Founder es intenso los 5 años | B9: =(Supuestos!$B$24+Supuestos!$B$27*Supuestos!$B$28+Supuestos!$B$29)*Supuestos!$B$11*60 -> 8494.956
A10: Contribución Founder por Stripe, usuario promedio (5 años) | B10: =B6-B8 -> 4551.2738
A11: Contribución Founder por Stripe, usuario intenso (5 años) | B11: =B6-B9 -> -1145.9422
A12: Los 50 Founders por Stripe: neto después de IVA y comisión (la caja bruta es 445,000; el IVA se remite) | B12: =B6*50 -> 367450.69
A13: Meses en que un Founder intenso agota el neto de Stripe | B13: =B6/((Supuestos!$B$24+Supuestos!$B$27*Supuestos!$B$28+Supuestos!$B$29)*Supuestos!$B$11) -> 51.906193
A14: Pro anual 3,990
A15: Precio con IVA | B15: =Supuestos!$B$8 -> 3990
A16: Equivalente mensual con IVA | B16: =B15/12 -> 332.5
A17: Descuento frente a 12 meses a 449 | B17: =1-B15/(Supuestos!$B$6*12) -> 0.25946548 | C17: Un 26% de descuento es el estándar de mercado para anual (2 a 3 meses gratis)
A18: Neto anual por Stripe | B18: =B15/(1+Supuestos!$B$10)-B15*Supuestos!$B$15-Supuestos!$B$16-B15*Supuestos!$B$17 -> 3265.0852
A19: Neto anual por App Store | B19: =B15/(1+Supuestos!$B$10)*(1-Supuestos!$B$13)-B15*Supuestos!$B$18 -> 2883.8069
A20: Costo de IA en el año (promedio) incluido el Diagnóstico ATP | B20: =(Supuestos!$B$23+Supuestos!$B$27*Supuestos!$B$28+Supuestos!$B$29)*Supuestos!$B$11*12+Supuestos!$B$30*Supuestos!$B$11 -> 562.9392
A21: Contribución anual por Stripe | B21: =B18-B20 -> 2702.146
A22: Contribución anual por App Store | B22: =B19-B20 -> 2320.8677

Sheet Fuentes
A1: Fuentes de cada número (vistas el 4 de septiembre de 2026)
A3: Dato | B3: Fuente | C3: Nota
A4: Apple, Small Business Program 15% | B4: https://developer.apple.com/app-store/small-business-program/ | C4: Menos de 1M USD de proceeds al año
A5: Apple, suscripciones 70/85 | B5: https://developer.apple.com/app-store/subscriptions/ | C5: 85% después del año 1; con SBP 85% desde el mes 1
A6: Apple, IVA México sobre precio sin IVA | B6: https://developer.apple.com/news/?id=oyy56t2r | C6: Comisión calculada sobre precio sin IVA; Apple remite el IVA
A7: Google Play, 15% suscripciones | B7: https://support.google.com/googleplay/android-developer/answer/112622 | C7: Sin cambio para México en 2026
A8: Google Play, IVA México | B8: https://support.google.com/googleplay/android-developer/answer/138000 | C8: Desarrollador en México remite el IVA de la venta; Google cobra IVA sobre su comisión
A9: Stripe México | B9: https://stripe.com/mx/pricing | C9: 3.6% + 3 MXN, Billing 0.7%, todo más IVA
A10: RevenueCat | B10: https://www.revenuecat.com/pricing/ | C10: Gratis hasta 2,500 USD MTR; 1% después
A11: Supabase | B11: https://supabase.com/pricing | C11: Pro 25 USD; 100k MAU; egress 250 GB
A12: Anthropic, Claude Sonnet 5 | B12: https://platform.claude.com/docs/en/about-claude/pricing | C12: 2 / 10 USD por M tokens; Sonnet 4.6: 3 / 15
A13: Gemini Flash | B13: https://ai.google.dev/gemini-api/docs/pricing | C13: 2.5 Flash 0.30 / 2.50 (respaldo del proxy)
A14: ElevenLabs | B14: https://elevenlabs.io/pricing/api | C14: Flash v2.5 0.05 USD por 1k caracteres
... A22: Lectura de laboratorios | B22: supabase/functions/lab-parser-worker/index.ts | C22: Sonnet 4.6 con PDF en base64. Costo por estudio ESTIMADO, no medido: pendiente
