Workbook

Sheet 0_README
A1: EDAD ATP MOTOR v1.0 — 5 ÁREAS CIEGAS
A3: Autoría algoritmo: | B3: Enrique Zapata
A4: Validación clínica: | B4: Dra. Mariana Doria
A5: Versión motor: | B5: 2.0 FINAL (arquitectura por áreas ciegas, anclaje por confiabilidad)
A6: Reemplaza: | B6: Motor v1 (SF global → curva piecewise)
A7: Matriz fuente: | B7: V8 HOMBRES + V8 MUJERES
A9: ARQUITECTURA
A10: 1. Cada área calcula UNA EDAD parcial (ciega, sin saber cronológica)
A11: 2. Cada edad parcial se ancla a cronológica con factor (evita extremos)
A12: 3. Promedio ponderado de las 5 áreas × modulador Hábitos = Edad ATP Integral
A13: 4. Clamp [20, 100]
A15: CONFIGURACIÓN (ajustable)
A16: Factor anclaje a cronológica | B16: 0.7 | C16: OBSOLETO — usar factores por área abajo
A17: Cap mínimo Edad ATP | B17: 20 | C17: Mínimo absoluto
A18: Cap máximo Edad ATP | B18: 100 | C18: Máximo absoluto
A19: Peso Labs Clínicos | B19: 0.25 | C19: PhenoAge + modificadores funcionales
A20: Peso Composición | B20: 0.15 | C20: FFMI + grasa + músculo + visceral
A21: Peso Fitness | B21: 0.2 | C21: VO2max + tests funcionales
A22: Peso Cognición | B22: 0.15 | C22: RT Simple + Choice + Go-NoGo + subjetivos
A23: Peso Riesgos | B23: 0.25 | C23: Cardio + metab + inflam + horm + hepato-renal
A24: FACTOR ANCLAJE POR ÁREA (CONFIG FINAL — congelada)
A25: Factor anclaje Labs | B25: 0.75 | C25: Alta: PhenoAge validado + labs duros | D25: ← CONFIG FINAL
A26: Factor anclaje Composición | B26: 0.7 | C26: Media-Alta: báscula + FFMI
A27: Factor anclaje Fitness | B27: 0.65 | C27: Media: tests in-app con motivación | D27: Perfil esperado (edad biológica)
A28: Factor anclaje Cognición | B28: 0.55 | C28: Media-Baja: subjetivos ruidosos | D28: ~50-55 (perfil sano-medio)
A29: Factor anclaje Riesgos | B29: 0.75 | C29: Alta: mayoría labs + sub-bloques diluidos | D29: ~22-28 (atleta GWR)
A30: M1 | B30: Mujer sintética joven optimizada | C30: 28 | D30: ~22-26 (atleta CrossFit)
A31: M2 | B31: Mujer sintética con riesgos | C31: 65 | D31: ~65-72 (sedentaria, DM2 controlada)

Sheet 1_Inputs
A1: INPUTS — todos los params por paciente
A3: Param | B3: Unidad | C3: H1 (cron 50) | D3: H2 Enrique (35) | E3: M1 Mujer (28) | F3: M2 Mujer (65) | G3: Notas
A4: — DATOS BÁSICOS —
A5: Edad cronológica | B5: años | C5: 50 | D5: 35.83 | E5: 28 | F5: 65
A6: Sexo (M=1, F=0) | B6: - | C6: 1 | D6: 1 | E6: 0 | F6: 0 | G6: Para fórmulas sexo-específicas
A8: — LABS PhenoAge (9 biomarkers) —
A9: Albúmina | B9: g/dL | C9: 5.28 | D9: 4.48 | E9: 4.7 | F9: 4
A10: Creatinina sérica | B10: mg/dL | C10: 0.81 | D10: 1.11 | E10: 0.78 | F10: 1.05
A11: Glucosa ayuno | B11: mg/dL | C11: 90 | D11: 75 | E11: 82 | F11: 105
A12: PCR (CRP) | B12: mg/dL | C12: 0.18 | D12: 0.2 | E12: 0.1 | F12: 0.5
A13: % Linfocitos | B13: % | C13: 33 | D13: 43 | E13: 38 | F13: 28
A14: VCM (MCV) | B14: fL | C14: 90 | D14: 88.6 | E14: 89 | F14: 92
A15: RDW-CV | B15: % | C15: 12.8 | D15: 12.9 | E15: 12.5 | F15: 14.2
A16: Fosfatasa Alcalina | B16: U/L | C16: 71 | D16: 57 | E16: 65 | F16: 80
A17: Leucocitos (WBC) | B17: ×10³/μL | C17: 7.4 | D17: 5.9 | E17: 6.2 | F17: 7.8
A19: — LABS modificadores funcionales —
A20: Vit D (25-OH) | B20: ng/mL | C20: 33.4 | D20: 51.8 | E20: 45 | F20: 22
A21: Vit B12 | B21: pg/mL | C21: 502 | D21: 163 | E21: 580 | F21: 350
A22: Homocisteína | B22: μmol/L | C22: 13.72 | D22: 8 | E22: 7 | F22: 14
A23: Ferritina | B23: ng/mL | C23: 291 | D23: 135 | E23: 80 | F23: 200
A24: TSH | B24: μUI/mL | C24: 1.57 | D24: 2.14 | E24: 1.8 | F24: 3.5
A25: Cortisol matutino | B25: μg/dL | C25: 8 | D25: 11.2 | E25: 12 | F25: 16
A26: Bilirrubina total | B26: mg/dL | C26: 0.57 | D26: 0.44 | E26: 0.6 | F26: 0.5
A28: — COMPOSICIÓN —
A29: Peso | B29: kg | C29: 87.4 | D29: 79 | E29: 60 | F29: 70
A30: Altura | B30: cm | C30: 183 | D30: 176 | E30: 165 | F30: 160
A31: % Grasa corporal | B31: % | C31: 24.2 | D31: 11 | E31: 18 | F31: 32
A32: % Músculo esquelético | B32: % | C32: 34.6 | D32: 50 | E32: 38 | F32: 25
A33: Grasa visceral | B33: índice | C33: 10 | D33: 3 | E33: 2 | F33: 9
A34: Cintura | B34: cm | C34: 95 | D34: 80 | E34: 65 | F34: 88
A35: Ratio cintura/cadera | B35: ratio | C35: 0.9 | D35: 0.83 | E35: 0.72 | F35: 0.85
A36: FFMI | B36: calc | C36: =POWER(D17/100,2)*0+87.4*(1-0.242)/POWER(1.83,2) | D36: 22.7 | E36: 17.5 | F36: 14.5 | G36: Calculado: peso×(1-%grasa)/altura²
A38: — FITNESS (tests) —
A39: VO2max estimado | B39: ml/kg/min | C39: 35 | D39: 55 | E39: 50 | F39: 22
A40: Push-ups máx continuas | B40: # | C40: 25 | D40: 60 | E40: 35 | F40: 5
A41: Sentadilla 60s | B41: # | C41: 30 | D41: 50 | E41: 45 | F41: 10
A42: Balance 1 pie ojos abiertos | B42: seg | C42: 45 | D42: 90 | E42: 120 | F42: 12
A43: Plank máx | B43: seg | C43: 90 | D43: 240 | E43: 180 | F43: 25
A44: BOLT | B44: seg | C44: 25 | D44: 40 | E44: 30 | F44: 15
A45: Recovery HR 2-min | B45: bpm caída | C45: 30 | D45: 50 | E45: 45 | F45: 18
...

Sheet 2_Area_Labs
A1: ÁREA 1 — LABS CLÍNICOS (PhenoAge Levine 2018 + Modificadores funcionales)
A3: Coeficientes PhenoAge (Levine 2018, Aging Cell)
A4: Variable | B4: Unidad modelo | C4: Coef K | D4: Conversión | E4: Referencia
A5: Intercept | B5: - | C5: -19.9067 | D5: - | E5: Levine 2018
A6: Albumin | B6: g/L | C6: -0.0336 | D6: × 10 (de g/dL) | E6: Mort risk ↓
A7: Creatinine | B7: μmol/L | C7: 0.0095 | D7: × 88.4 (de mg/dL) | E7: Renal
A8: Glucose | B8: mmol/L | C8: 0.1953 | D8: × 0.0555 (de mg/dL) | E8: Metabólico
A9: ln(CRP × 10) | B9: mg/dL→ln | C9: 0.0954 | D9: LN(CRP×10) | E9: Inflamación
A10: Lymphocyte % | B10: % | C10: -0.012 | D10: directo | E10: Inmune
A11: MCV | B11: fL | C11: 0.0268 | D11: directo | E11: Hemato
A12: RDW | B12: % | C12: 0.3306 | D12: directo (no ×100) | E12: Estrés eritrocitario
A13: ALP | B13: U/L | C13: 0.00188 | D13: directo | E13: Hepato-óseo
A14: WBC | B14: ×10³/μL | C14: 0.0554 | D14: ÷ 1000 (de /μL) | E14: Inmune
A15: Age cronológica | B15: años | C15: 0.0804 | D15: directo | E15: Reloj base
A17: CÁLCULO PhenoAge por paciente
A18: Paso | B18: Fórmula | C18: H1 | D18: H2 Enrique | E18: M1 | F18: M2
A19: VPA Albumin | B19: input row 9 × C6 | C19: =('1_Inputs'!C9*10)*C6 | D19: =('1_Inputs'!D9*10)*C6 | E19: =('1_Inputs'!E9*10)*C6 | F19: =('1_Inputs'!F9*10)*C6
A20: VPA Creatinine | B20: input row 10 × C7 | C20: =('1_Inputs'!C10*88.4)*C7 | D20: =('1_Inputs'!D10*88.4)*C7 | E20: =('1_Inputs'!E10*88.4)*C7 | F20: =('1_Inputs'!F10*88.4)*C7
A21: VPA Glucose | B21: input row 11 × C8 | C21: =('1_Inputs'!C11*0.0555)*C8 | D21: =('1_Inputs'!D11*0.0555)*C8 | E21: =('1_Inputs'!E11*0.0555)*C8 | F21: =('1_Inputs'!F11*0.0555)*C8
A22: VPA ln(CRP) | B22: input row 12 × C9 | C22: =LN(MAX('1_Inputs'!C12*10,0.0001))*C9 | D22: =LN(MAX('1_Inputs'!D12*10,0.0001))*C9 | E22: =LN(MAX('1_Inputs'!E12*10,0.0001))*C9 | F22: =LN(MAX('1_Inputs'!F12*10,0.0001))*C9
A23: VPA Lymphocyte% | B23: input row 13 × C10 | C23: ='1_Inputs'!C13*C10 | D23: ='1_Inputs'!D13*C10 | E23: ='1_Inputs'!E13*C10 | F23: ='1_Inputs'!F13*C10
A24: VPA MCV | B24: input row 14 × C11 | C24: ='1_Inputs'!C14*C11 | D24: ='1_Inputs'!D14*C11 | E24: ='1_Inputs'!E14*C11 | F24: ='1_Inputs'!F14*C11
A25: VPA RDW | B25: input row 15 × C12 | C25: ='1_Inputs'!C15*C12 | D25: ='1_Inputs'!D15*C12 | E25: ='1_Inputs'!E15*C12 | F25: ='1_Inputs'!F15*C12
A26: VPA ALP | B26: input row 16 × C13 | C26: ='1_Inputs'!C16*C13 | D26: ='1_Inputs'!D16*C13 | E26: ='1_Inputs'!E16*C13 | F26: ='1_Inputs'!F16*C13
A27: VPA WBC | B27: input row 17 × C14 | C27: ='1_Inputs'!C17*C14 | D27: ='1_Inputs'!D17*C14 | E27: ='1_Inputs'!E17*C14 | F27: ='1_Inputs'!F17*C14
A28: VPA Age | B28: input row 5 × C15 | C28: ='1_Inputs'!C5*C15 | D28: ='1_Inputs'!D5*C15 | E28: ='1_Inputs'!E5*C15 | F28: ='1_Inputs'!F5*C15
A29: xb (linear predictor) | B29: Intercept + Σ VPA | C29: =-19.9067+SUM(C19:C28) | D29: =-19.9067+SUM(D19:D28) | E29: =-19.9067+SUM(E19:E28) | F29: =-19.9067+SUM(F19:F28)
A30: Mort_Score | B30: =1-EXP(-EXP(xb) × ((EXP(0.0076927×120)-1)/0.0076927)) | C30: =1-EXP(-EXP(C29)*((EXP(0.0076927*120)-1)/0.0076927)) | D30: =1-EXP(-EXP(D29)*((EXP(0.0076927*120)-1)/0.0076927)) | E30: =1-EXP(-EXP(E29)*((EXP(0.0076927*120)-1)/0.0076927)) | F30: =1-EXP(-EXP(F29)*((EXP(0.0076927*120)-1)/0.0076927))
A31: PhenoAge (Levine 2018) | B31: =141.50225 + ln(-0.00553×ln(1-MortScore))/0.090165 | C31: =141.50225+LN(-0.00553*LN(1-C30))/0.090165 | D31: =141.50225+LN(-0.00553*LN(1-D30))/0.090165 | E31: =141.50225+LN(-0.00553*LN(1-E30))/0.090165 | F31: =141.50225+LN(-0.00553*LN(1-F30))/0.090165
A33: MODIFICADORES FUNCIONALES (delta a PhenoAge)
A34: Variable | B34: Regla | C34: H1 | D34: H2 | E34: M1 | F34: M2
A35: Vit D modif | B35: <30→+1, 30-50→0, 50-70→-1, >70→+0.5 | C35: =IF('1_Inputs'!C20<30,1,IF('1_Inputs'!C20>70,0.5,IF('1_Inputs'!C20<50,0,-1))) | D35: =IF('1_Inputs'!D20<30,1,IF('1_Inputs'!D20>70,0.5,IF('1_Inputs'!D20<50,0,-1))) | E35: =IF('1_Inputs'!E20<30,1,IF('1_Inputs'!E20>70,0.5,IF('1_Inputs'!E20<50,0,-1))) | F35: =IF('1_Inputs'!F20<30,1,IF('1_Inputs'!F20>70,0.5,IF('1_Inputs'!F20<50,0,-1)))
A36: Vit B12 modif | B36: <200→+2, 200-400→+0.5, 400-700→-0.5, >700→0 | C36: =IF('1_Inputs'!C21<200,2,IF('1_Inputs'!C21<400,0.5,IF('1_Inputs'!C21<700,-0.5,0))) | D36: =IF('1_Inputs'!D21<200,2,IF('1_Inputs'!D21<400,0.5,IF('1_Inputs'!D21<700,-0.5,0))) | E36: =IF('1_Inputs'!E21<200,2,IF('1_Inputs'!E21<400,0.5,IF('1_Inputs'!E21<700,-0.5,0))) | F36: =IF('1_Inputs'!F21<200,2,IF('1_Inputs'!F21<400,0.5,IF('1_Inputs'!F21<700,-0.5,0)))
A37: Homocist modif | B37: <8→-1, 8-12→0, 12-15→+1, >15→+2 | C37: =IF('1_Inputs'!C22<8,-1,IF('1_Inputs'!C22<12,0,IF('1_Inputs'!C22<15,1,2))) | D37: =IF('1_Inputs'!D22<8,-1,IF('1_Inputs'!D22<12,0,IF('1_Inputs'!D22<15,1,2))) | E37: =IF('1_Inputs'!E22<8,-1,IF('1_Inputs'!E22<12,0,IF('1_Inputs'!E22<15,1,2))) | F37: =IF('1_Inputs'!F22<8,-1,IF('1_Inputs'!F22<12,0,IF('1_Inputs'!F22<15,1,2)))
A38: Ferritina modif | B38: en rango (30-300)→-0.5, fuera→+1 | C38: =IF(AND('1_Inputs'!C23>=30,'1_Inputs'!C23<=300),-0.5,1) | D38: =IF(AND('1_Inputs'!D23>=30,'1_Inputs'!D23<=300),-0.5,1) | E38: =IF(AND('1_Inputs'!E23>=30,'1_Inputs'!E23<=300),-0.5,1) | F38: =IF(AND('1_Inputs'!F23>=30,'1_Inputs'!F23<=300),-0.5,1)
A39: TSH modif | B39: óptimo 1-2.5→-0.5, 2.5-4→0, fuera→+1 | C39: =IF(AND('1_Inputs'!C24>=1,'1_Inputs'!C24<=2.5),-0.5,IF(AND('1_Inputs'!C24>2.5,'1_Inputs'!C24<=4),0,1)) | D39: =IF(AND('1_Inputs'!D24>=1,'1_Inputs'!D24<=2.5),-0.5,IF(AND('1_Inputs'!D24>2.5,'1_Inputs'!D24<=4),0,1)) | E39: =IF(AND('1_Inputs'!E24>=1,'1_Inputs'!E24<=2.5),-0.5,IF(AND('1_Inputs'!E24>2.5,'1_Inputs'!E24<=4),0,1)) | F39: =IF(AND('1_Inputs'!F24>=1,'1_Inputs'!F24<=2.5),-0.5,IF(AND('1_Inputs'!F24>2.5,'1_Inputs'!F24<=4),0,1))
A40: Cortisol modif | B40: óptimo 8-15→0, <8 ó >15→+1 | C40: =IF(AND('1_Inputs'!C25>=8,'1_Inputs'!C25<=15),0,1) | D40: =IF(AND('1_Inputs'!D25>=8,'1_Inputs'!D25<=15),0,1) | E40: =IF(AND('1_Inputs'!E25>=8,'1_Inputs'!E25<=15),0,1) | F40: =IF(AND('1_Inputs'!F25>=8,'1_Inputs'!F25<=15),0,1)
A41: Bilirrubina modif | B41: en rango 0.3-1.2→-0.5 (antioxidante), fuera→+0.5 | C41: =IF(AND('1_Inputs'!C26>=0.3,'1_Inputs'!C26<=1.2),-0.5,0.5) | D41: =IF(AND('1_Inputs'!D26>=0.3,'1_Inputs'!D26<=1.2),-0.5,0.5) | E41: =IF(AND('1_Inputs'!E26>=0.3,'1_Inputs'!E26<=1.2),-0.5,0.5) | F41: =IF(AND('1_Inputs'!F26>=0.3,'1_Inputs'!F26<=1.2),-0.5,0.5)
A42: Suma modificadores | B42: Σ deltas (cap interno [-5, +10]) | C42: =MAX(-5,MIN(10,SUM(C35:C41))) | D42: =MAX(-5,MIN(10,SUM(D35:D41))) | E42: =MAX(-5,MIN(10,SUM(E35:E41))) | F42: =MAX(-5,MIN(10,SUM(F35:F41)))
A44: ═══ EDAD LABS (parcial) ═══ | B44: PhenoAge + suma modificadores | C44: =C31+C42 | D44: =D31+D42 | E44: =E31+E42 | F44: =F31+F42
...

Sheet 3_Area_Composicion
A1: ÁREA 2 — COMPOSICIÓN CORPORAL
A3: Bandas por sexo (literatura + matriz V8). Score 0-100 por param, luego promedio ponderado.
A5: Param | B5: Peso | C5: H1 score | D5: H2 score | E5: M1 score | F5: M2 score
A6: % Grasa corporal | B6: 0.2 | C6: =IF('1_Inputs'!C6=1,IF(AND('1_Inputs'!C31>=10,'1_Inputs'!C31<=14),100,IF(AND('1_Inputs'!C31>=8,'1_Inputs'!C31<10),90,IF(AND('1_Inputs'!C31>14,'1_Inputs'!C31<=18.5),80,IF(AND('1_Inputs'!C31>18.5,'1_Inputs'!C31<=24),50,IF('1_Inputs'!C31>24,25,IF('1_Inputs'!C31<8,80,0)))))),IF(AND('1_Inputs'!C31>=18,'1_Inputs'!C31<=23),100,IF(AND('1_Inputs'!C31>=15,'1_Inputs'!C31<18),90,IF(AND('1_Inputs'!C31>23,'1_Inputs'!C31<=28),80,IF(AND('1_Inputs'!C31>28,'1_Inputs'!C31<=33),50,IF('1_Inputs'!C31>33,25,IF('1_Inputs'!C31<15,80,0))))))) | D6: =IF('1_Inputs'!D6=1,IF(AND('1_Inputs'!D31>=10,'1_Inputs'!D31<=14),100,IF(AND('1_Inputs'!D31>=8,'1_Inputs'!D31<10),90,IF(AND('1_Inputs'!D31>14,'1_Inputs'!D31<=18.5),80,IF(AND('1_Inputs'!D31>18.5,'1_Inputs'!D31<=24),50,IF('1_Inputs'!D31>24,25,IF('1_Inputs'!D31<8,80,0)))))),IF(AND('1_Inputs'!D31>=18,'1_Inputs'!D31<=23),100,IF(AND('1_Inputs'!D31>=15,'1_Inputs'!D31<18),90,IF(AND('1_Inputs'!D31>23,'1_Inputs'!D31<=28),80,IF(AND('1_Inputs'!D31>28,'1_Inputs'!D31<=33),50,IF('1_Inputs'!D31>33,25,IF('1_Inputs'!D31<15,80,0))))))) | E6: =IF('1_Inputs'!E6=1,IF(AND('1_Inputs'!E31>=10,'1_Inputs'!E31<=14),100,IF(AND('1_Inputs'!E31>=8,'1_Inputs'!E31<10),90,IF(AND('1_Inputs'!E31>14,'1_Inputs'!E31<=18.5),80,IF(AND('1_Inputs'!E31>18.5,'1_Inputs'!E31<=24),50,IF('1_Inputs'!E31>24,25,IF('1_Inputs'!E31<8,80,0)))))),IF(AND('1_Inputs'!E31>=18,'1_Inputs'!E31<=23),100,IF(AND('1_Inputs'!E31>=15,'1_Inputs'!E31<18),90,IF(AND('1_Inputs'!E31>23,'1_Inputs'!E31<=28),80,IF(AND('1_Inputs'!E31>28,'1_Inputs'!E31<=33),50,IF('1_Inputs'!E31>33,25,IF('1_Inputs'!E31<15,80,0))))))) | F6: =IF('1_Inputs'!F6=1,IF(AND('1_Inputs'!F31>=10,'1_Inputs'!F31<=14),100,IF(AND('1_Inputs'!F31>=8,'1_Inputs'!F31<10),90,IF(AND('1_Inputs'!F31>14,'1_Inputs'!F31<=18.5),80,IF(AND('1_Inputs'!F31>18.5,'1_Inputs'!F31<=24),50,IF('1_Inputs'!F31>24,25,IF('1_Inputs'!F31<8,80,0)))))),IF(AND('1_Inputs'!F31>=18,'1_Inputs'!F31<=23),100,IF(AND('1_Inputs'!F31>=15,'1_Inputs'!F31<18),90,IF(AND('1_Inputs'!F31>23,'1_Inputs'!F31<=28),80,IF(AND('1_Inputs'!F31>28,'1_Inputs'!F31<=33),50,IF('1_Inputs'!F31>33,25,IF('1_Inputs'!F31<15,80,0)))))))
A7: FFMI | B7: 0.2 | C7: =IF('1_Inputs'!C6=1,IF(('1_Inputs'!C29*(1-'1_Inputs'!C31/100)/(('1_Inputs'!C30/100)^2))<17.5,25,IF(('1_Inputs'!C29*(1-'1_Inputs'!C31/100)/(('1_Inputs'!C30/100)^2))<19,50,IF(('1_Inputs'!C29*(1-'1_Inputs'!C31/100)/(('1_Inputs'!C30/100)^2))<22,80,IF(('1_Inputs'!C29*(1-'1_Inputs'!C31/100)/(('1_Inputs'!C30/100)^2))<=25,100,80)))),IF(('1_Inputs'!C29*(1-'1_Inputs'!C31/100)/(('1_Inputs'!C30/100)^2))<14,25,IF(('1_Inputs'!C29*(1-'1_Inputs'!C31/100)/(('1_Inputs'!C30/100)^2))<15.5,50,IF(('1_Inputs'!C29*(1-'1_Inputs'!C31/100)/(('1_Inputs'!C30/100)^2))<17,80,IF(('1_Inputs'!C29*(1-'1_Inputs'!C31/100)/(('1_Inputs'!C30/100)^2))<=19,100,80))))) | D7: =IF('1_Inputs'!D6=1,IF(('1_Inputs'!D29*(1-'1_Inputs'!D31/100)/(('1_Inputs'!D30/100)^2))<17.5,25,IF(('1_Inputs'!D29*(1-'1_Inputs'!D31/100)/(('1_Inputs'!D30/100)^2))<19,50,IF(('1_Inputs'!D29*(1-'1_Inputs'!D31/100)/(('1_Inputs'!D30/100)^2))<22,80,IF(('1_Inputs'!D29*(1-'1_Inputs'!D31/100)/(('1_Inputs'!D30/100)^2))<=25,100,80)))),IF(('1_Inputs'!D29*(1-'1_Inputs'!D31/100)/(('1_Inputs'!D30/100)^2))<14,25,IF(('1_Inputs'!D29*(1-'1_Inputs'!D31/100)/(('1_Inputs'!D30/100)^2))<15.5,50,IF(('1_Inputs'!D29*(1-'1_Inputs'!D31/100)/(('1_Inputs'!D30/100)^2))<17,80,IF(('1_Inputs'!D29*(1-'1_Inputs'!D31/100)/(('1_Inputs'!D30/100)^2))<=19,100,80))))) | E7: =IF('1_Inputs'!E6=1,IF(('1_Inputs'!E29*(1-'1_Inputs'!E31/100)/(('1_Inputs'!E30/100)^2))<17.5,25,IF(('1_Inputs'!E29*(1-'1_Inputs'!E31/100)/(('1_Inputs'!E30/100)^2))<19,50,IF(('1_Inputs'!E29*(1-'1_Inputs'!E31/100)/(('1_Inputs'!E30/100)^2))<22,80,IF(('1_Inputs'!E29*(1-'1_Inputs'!E31/100)/(('1_Inputs'!E30/100)^2))<=25,100,80)))),IF(('1_Inputs'!E29*(1-'1_Inputs'!E31/100)/(('1_Inputs'!E30/100)^2))<14,25,IF(('1_Inputs'!E29*(1-'1_Inputs'!E31/100)/(('1_Inputs'!E30/100)^2))<15.5,50,IF(('1_Inputs'!E29*(1-'1_Inputs'!E31/100)/(('1_Inputs'!E30/100)^2))<17,80,IF(('1_Inputs'!E29*(1-'1_Inputs'!E31/100)/(('1_Inputs'!E30/100)^2))<=19,100,80))))) | F7: =IF('1_Inputs'!F6=1,IF(('1_Inputs'!F29*(1-'1_Inputs'!F31/100)/(('1_Inputs'!F30/100)^2))<17.5,25,IF(('1_Inputs'!F29*(1-'1_Inputs'!F31/100)/(('1_Inputs'!F30/100)^2))<19,50,IF(('1_Inputs'!F29*(1-'1_Inputs'!F31/100)/(('1_Inputs'!F30/100)^2))<22,80,IF(('1_Inputs'!F29*(1-'1_Inputs'!F31/100)/(('1_Inputs'!F30/100)^2))<=25,100,80)))),IF(('1_Inputs'!F29*(1-'1_Inputs'!F31/100)/(('1_Inputs'!F30/100)^2))<14,25,IF(('1_Inputs'!F29*(1-'1_Inputs'!F31/100)/(('1_Inputs'!F30/100)^2))<15.5,50,IF(('1_Inputs'!F29*(1-'1_Inputs'!F31/100)/(('1_Inputs'!F30/100)^2))<17,80,IF(('1_Inputs'!F29*(1-'1_Inputs'!F31/100)/(('1_Inputs'!F30/100)^2))<=19,100,80)))))
A8: % Músculo esquelético | B8: 0.2 | C8: =IF('1_Inputs'!C6=1,IF('1_Inputs'!C32>=45,100,IF('1_Inputs'!C32>=40,80,IF('1_Inputs'!C32>=35,50,IF('1_Inputs'!C32>=30,25,0)))),IF('1_Inputs'!C32>=35,100,IF('1_Inputs'!C32>=32,80,IF('1_Inputs'!C32>=28,50,IF('1_Inputs'!C32>=25,25,0))))) | D8: =IF('1_Inputs'!D6=1,IF('1_Inputs'!D32>=45,100,IF('1_Inputs'!D32>=40,80,IF('1_Inputs'!D32>=35,50,IF('1_Inputs'!D32>=30,25,0)))),IF('1_Inputs'!D32>=35,100,IF('1_Inputs'!D32>=32,80,IF('1_Inputs'!D32>=28,50,IF('1_Inputs'!D32>=25,25,0))))) | E8: =IF('1_Inputs'!E6=1,IF('1_Inputs'!E32>=45,100,IF('1_Inputs'!E32>=40,80,IF('1_Inputs'!E32>=35,50,IF('1_Inputs'!E32>=30,25,0)))),IF('1_Inputs'!E32>=35,100,IF('1_Inputs'!E32>=32,80,IF('1_Inputs'!E32>=28,50,IF('1_Inputs'!E32>=25,25,0))))) | F8: =IF('1_Inputs'!F6=1,IF('1_Inputs'!F32>=45,100,IF('1_Inputs'!F32>=40,80,IF('1_Inputs'!F32>=35,50,IF('1_Inputs'!F32>=30,25,0)))),IF('1_Inputs'!F32>=35,100,IF('1_Inputs'!F32>=32,80,IF('1_Inputs'!F32>=28,50,IF('1_Inputs'!F32>=25,25,0)))))
A9: Grasa visceral | B9: 0.15 | C9: =IF('1_Inputs'!C6=1,IF('1_Inputs'!C33<5,100,IF('1_Inputs'!C33<=7,80,IF('1_Inputs'!C33<=10,50,IF('1_Inputs'!C33<=12,25,0)))),IF('1_Inputs'!C33<4,100,IF('1_Inputs'!C33<=6,80,IF('1_Inputs'!C33<=8,50,IF('1_Inputs'!C33<=10,25,0))))) | D9: =IF('1_Inputs'!D6=1,IF('1_Inputs'!D33<5,100,IF('1_Inputs'!D33<=7,80,IF('1_Inputs'!D33<=10,50,IF('1_Inputs'!D33<=12,25,0)))),IF('1_Inputs'!D33<4,100,IF('1_Inputs'!D33<=6,80,IF('1_Inputs'!D33<=8,50,IF('1_Inputs'!D33<=10,25,0))))) | E9: =IF('1_Inputs'!E6=1,IF('1_Inputs'!E33<5,100,IF('1_Inputs'!E33<=7,80,IF('1_Inputs'!E33<=10,50,IF('1_Inputs'!E33<=12,25,0)))),IF('1_Inputs'!E33<4,100,IF('1_Inputs'!E33<=6,80,IF('1_Inputs'!E33<=8,50,IF('1_Inputs'!E33<=10,25,0))))) | F9: =IF('1_Inputs'!F6=1,IF('1_Inputs'!F33<5,100,IF('1_Inputs'!F33<=7,80,IF('1_Inputs'!F33<=10,50,IF('1_Inputs'!F33<=12,25,0)))),IF('1_Inputs'!F33<4,100,IF('1_Inputs'!F33<=6,80,IF('1_Inputs'!F33<=8,50,IF('1_Inputs'!F33<=10,25,0)))))
A10: Fuerza de agarre | B10: 0.15 | C10: =IF('1_Inputs'!C6=1,IF('1_Inputs'!C47>55,100,IF('1_Inputs'!C47>=45,80,IF('1_Inputs'!C47>=35,50,IF('1_Inputs'!C47>=25,25,0)))),IF('1_Inputs'!C47>35,100,IF('1_Inputs'!C47>=28,80,IF('1_Inputs'!C47>=22,50,IF('1_Inputs'!C47>=18,25,0))))) | D10: =IF('1_Inputs'!D6=1,IF('1_Inputs'!D47>55,100,IF('1_Inputs'!D47>=45,80,IF('1_Inputs'!D47>=35,50,IF('1_Inputs'!D47>=25,25,0)))),IF('1_Inputs'!D47>35,100,IF('1_Inputs'!D47>=28,80,IF('1_Inputs'!D47>=22,50,IF('1_Inputs'!D47>=18,25,0))))) | E10: =IF('1_Inputs'!E6=1,IF('1_Inputs'!E47>55,100,IF('1_Inputs'!E47>=45,80,IF('1_Inputs'!E47>=35,50,IF('1_Inputs'!E47>=25,25,0)))),IF('1_Inputs'!E47>35,100,IF('1_Inputs'!E47>=28,80,IF('1_Inputs'!E47>=22,50,IF('1_Inputs'!E47>=18,25,0))))) | F10: =IF('1_Inputs'!F6=1,IF('1_Inputs'!F47>55,100,IF('1_Inputs'!F47>=45,80,IF('1_Inputs'!F47>=35,50,IF('1_Inputs'!F47>=25,25,0)))),IF('1_Inputs'!F47>35,100,IF('1_Inputs'!F47>=28,80,IF('1_Inputs'!F47>=22,50,IF('1_Inputs'!F47>=18,25,0)))))
A11: Cintura | B11: 0.1 | C11: =IF('1_Inputs'!C6=1,IF('1_Inputs'!C34<94,100,IF('1_Inputs'!C34<=102,50,0)),IF('1_Inputs'!C34<80,100,IF('1_Inputs'!C34<=88,50,0))) | D11: =IF('1_Inputs'!D6=1,IF('1_Inputs'!D34<94,100,IF('1_Inputs'!D34<=102,50,0)),IF('1_Inputs'!D34<80,100,IF('1_Inputs'!D34<=88,50,0))) | E11: =IF('1_Inputs'!E6=1,IF('1_Inputs'!E34<94,100,IF('1_Inputs'!E34<=102,50,0)),IF('1_Inputs'!E34<80,100,IF('1_Inputs'!E34<=88,50,0))) | F11: =IF('1_Inputs'!F6=1,IF('1_Inputs'!F34<94,100,IF('1_Inputs'!F34<=102,50,0)),IF('1_Inputs'!F34<80,100,IF('1_Inputs'!F34<=88,50,0)))
A12: Score Composición (0-100) | B12: Σ score×peso | C12: =SUMPRODUCT(C6:C11,$B$6:$B$11) | D12: =SUMPRODUCT(D6:D11,$B$6:$B$11) | E12: =SUMPRODUCT(E6:E11,$B$6:$B$11) | F12: =SUMPRODUCT(F6:F11,$B$6:$B$11)
A13: ═══ EDAD COMPOSICIÓN (ciega) ═══ | B13: Mapeo score→edad universal | C13: =IF(C12>=95,22,IF(C12>=90,28-(C12-90)/5*6,IF(C12>=80,33-(C12-80)/10*5,IF(C12>=70,42-(C12-70)/10*9,IF(C12>=60,50-(C12-60)/10*8,IF(C12>=50,60-(C12-50)/10*10,IF(C12>=40,70-(C12-40)/10*10,IF(C12>=30,80-(C12-30)/10*10,MIN(100,90+(30-C12)/30*10))))))))) | D13: =IF(D12>=95,22,IF(D12>=90,28-(D12-90)/5*6,IF(D12>=80,33-(D12-80)/10*5,IF(D12>=70,42-(D12-70)/10*9,IF(D12>=60,50-(D12-60)/10*8,IF(D12>=50,60-(D12-50)/10*10,IF(D12>=40,70-(D12-40)/10*10,IF(D12>=30,80-(D12-30)/10*10,MIN(100,90+(30-D12)/30*10))))))))) | E13: =IF(E12>=95,22,IF(E12>=90,28-(E12-90)/5*6,IF(E12>=80,33-(E12-80)/10*5,IF(E12>=70,42-(E12-70)/10*9,IF(E12>=60,50-(E12-60)/10*8,IF(E12>=50,60-(E12-50)/10*10,IF(E12>=40,70-(E12-40)/10*10,IF(E12>=30,80-(E12-30)/10*10,MIN(100,90+(30-E12)/30*10))))))))) | F13: =IF(F12>=95,22,IF(F12>=90,28-(F12-90)/5*6,IF(F12>=80,33-(F12-80)/10*5,IF(F12>=70,42-(F12-70)/10*9,IF(F12>=60,50-(F12-60)/10*8,IF(F12>=50,60-(F12-50)/10*10,IF(F12>=40,70-(F12-40)/10*10,IF(F12>=30,80-(F12-30)/10*10,MIN(100,90+(30-F12)/30*10)))))))))

Sheet 4_Area_Fitness
A1: ÁREA 3 — FITNESS / CAPACIDAD FÍSICA
A3: Tests funcionales con curvas por sexo (literatura). Score 0-100 por test → score ponderado → edad ciega.
A4: Refs: ACSM (VO2max), Yang 2019 (push-ups), Brito 2014 (Old Man Test/Sit-Rise), Berg (balance), Leong 2015 (agarre).
A6: Test | B6: Peso | C6: H1 score | D6: H2 score | E6: M1 score | F6: M2 score
A7: VO2max estimado | B7: 0.25 | C7: =IF('1_Inputs'!C6=1,IF('1_Inputs'!C39>55,100,IF('1_Inputs'!C39>=45,80,IF('1_Inputs'!C39>=35,50,IF('1_Inputs'!C39>=30,25,0)))),IF('1_Inputs'!C39>45,100,IF('1_Inputs'!C39>=38,80,IF('1_Inputs'!C39>=30,50,IF('1_Inputs'!C39>=25,25,0))))) | D7: =IF('1_Inputs'!D6=1,IF('1_Inputs'!D39>55,100,IF('1_Inputs'!D39>=45,80,IF('1_Inputs'!D39>=35,50,IF('1_Inputs'!D39>=30,25,0)))),IF('1_Inputs'!D39>45,100,IF('1_Inputs'!D39>=38,80,IF('1_Inputs'!D39>=30,50,IF('1_Inputs'!D39>=25,25,0))))) | E7: =IF('1_Inputs'!E6=1,IF('1_Inputs'!E39>55,100,IF('1_Inputs'!E39>=45,80,IF('1_Inputs'!E39>=35,50,IF('1_Inputs'!E39>=30,25,0)))),IF('1_Inputs'!E39>45,100,IF('1_Inputs'!E39>=38,80,IF('1_Inputs'!E39>=30,50,IF('1_Inputs'!E39>=25,25,0))))) | F7: =IF('1_Inputs'!F6=1,IF('1_Inputs'!F39>55,100,IF('1_Inputs'!F39>=45,80,IF('1_Inputs'!F39>=35,50,IF('1_Inputs'!F39>=30,25,0)))),IF('1_Inputs'!F39>45,100,IF('1_Inputs'!F39>=38,80,IF('1_Inputs'!F39>=30,50,IF('1_Inputs'!F39>=25,25,0)))))
A8: Fuerza de agarre | B8: 0.15 | C8: =IF('1_Inputs'!C6=1,IF('1_Inputs'!C47>55,100,IF('1_Inputs'!C47>=45,80,IF('1_Inputs'!C47>=35,50,IF('1_Inputs'!C47>=25,25,0)))),IF('1_Inputs'!C47>35,100,IF('1_Inputs'!C47>=28,80,IF('1_Inputs'!C47>=22,50,IF('1_Inputs'!C47>=18,25,0))))) | D8: =IF('1_Inputs'!D6=1,IF('1_Inputs'!D47>55,100,IF('1_Inputs'!D47>=45,80,IF('1_Inputs'!D47>=35,50,IF('1_Inputs'!D47>=25,25,0)))),IF('1_Inputs'!D47>35,100,IF('1_Inputs'!D47>=28,80,IF('1_Inputs'!D47>=22,50,IF('1_Inputs'!D47>=18,25,0))))) | E8: =IF('1_Inputs'!E6=1,IF('1_Inputs'!E47>55,100,IF('1_Inputs'!E47>=45,80,IF('1_Inputs'!E47>=35,50,IF('1_Inputs'!E47>=25,25,0)))),IF('1_Inputs'!E47>35,100,IF('1_Inputs'!E47>=28,80,IF('1_Inputs'!E47>=22,50,IF('1_Inputs'!E47>=18,25,0))))) | F8: =IF('1_Inputs'!F6=1,IF('1_Inputs'!F47>55,100,IF('1_Inputs'!F47>=45,80,IF('1_Inputs'!F47>=35,50,IF('1_Inputs'!F47>=25,25,0)))),IF('1_Inputs'!F47>35,100,IF('1_Inputs'!F47>=28,80,IF('1_Inputs'!F47>=22,50,IF('1_Inputs'!F47>=18,25,0)))))
A9: Old Man Test (Brito 2014) | B9: 0.15 | C9: =IF('1_Inputs'!C46>=10,100,IF('1_Inputs'!C46>=8,80,IF('1_Inputs'!C46>=6,50,IF('1_Inputs'!C46>=4,25,0)))) | D9: =IF('1_Inputs'!D46>=10,100,IF('1_Inputs'!D46>=8,80,IF('1_Inputs'!D46>=6,50,IF('1_Inputs'!D46>=4,25,0)))) | E9: =IF('1_Inputs'!E46>=10,100,IF('1_Inputs'!E46>=8,80,IF('1_Inputs'!E46>=6,50,IF('1_Inputs'!E46>=4,25,0)))) | F9: =IF('1_Inputs'!F46>=10,100,IF('1_Inputs'!F46>=8,80,IF('1_Inputs'!F46>=6,50,IF('1_Inputs'!F46>=4,25,0))))
A10: Push-ups máximas | B10: 0.1 | C10: =IF('1_Inputs'!C6=1,IF('1_Inputs'!C40>=40,100,IF('1_Inputs'!C40>=25,80,IF('1_Inputs'!C40>=15,50,IF('1_Inputs'!C40>=10,25,0)))),IF('1_Inputs'!C40>=25,100,IF('1_Inputs'!C40>=15,80,IF('1_Inputs'!C40>=8,50,IF('1_Inputs'!C40>=5,25,0))))) | D10: =IF('1_Inputs'!D6=1,IF('1_Inputs'!D40>=40,100,IF('1_Inputs'!D40>=25,80,IF('1_Inputs'!D40>=15,50,IF('1_Inputs'!D40>=10,25,0)))),IF('1_Inputs'!D40>=25,100,IF('1_Inputs'!D40>=15,80,IF('1_Inputs'!D40>=8,50,IF('1_Inputs'!D40>=5,25,0))))) | E10: =IF('1_Inputs'!E6=1,IF('1_Inputs'!E40>=40,100,IF('1_Inputs'!E40>=25,80,IF('1_Inputs'!E40>=15,50,IF('1_Inputs'!E40>=10,25,0)))),IF('1_Inputs'!E40>=25,100,IF('1_Inputs'!E40>=15,80,IF('1_Inputs'!E40>=8,50,IF('1_Inputs'!E40>=5,25,0))))) | F10: =IF('1_Inputs'!F6=1,IF('1_Inputs'!F40>=40,100,IF('1_Inputs'!F40>=25,80,IF('1_Inputs'!F40>=15,50,IF('1_Inputs'!F40>=10,25,0)))),IF('1_Inputs'!F40>=25,100,IF('1_Inputs'!F40>=15,80,IF('1_Inputs'!F40>=8,50,IF('1_Inputs'!F40>=5,25,0)))))
A11: Sentadilla 60s | B11: 0.1 | C11: =IF('1_Inputs'!C6=1,IF('1_Inputs'!C41>=40,100,IF('1_Inputs'!C41>=30,80,IF('1_Inputs'!C41>=20,50,IF('1_Inputs'!C41>=10,25,0)))),IF('1_Inputs'!C41>=35,100,IF('1_Inputs'!C41>=25,80,IF('1_Inputs'!C41>=15,50,IF('1_Inputs'!C41>=8,25,0))))) | D11: =IF('1_Inputs'!D6=1,IF('1_Inputs'!D41>=40,100,IF('1_Inputs'!D41>=30,80,IF('1_Inputs'!D41>=20,50,IF('1_Inputs'!D41>=10,25,0)))),IF('1_Inputs'!D41>=35,100,IF('1_Inputs'!D41>=25,80,IF('1_Inputs'!D41>=15,50,IF('1_Inputs'!D41>=8,25,0))))) | E11: =IF('1_Inputs'!E6=1,IF('1_Inputs'!E41>=40,100,IF('1_Inputs'!E41>=30,80,IF('1_Inputs'!E41>=20,50,IF('1_Inputs'!E41>=10,25,0)))),IF('1_Inputs'!E41>=35,100,IF('1_Inputs'!E41>=25,80,IF('1_Inputs'!E41>=15,50,IF('1_Inputs'!E41>=8,25,0))))) | F11: =IF('1_Inputs'!F6=1,IF('1_Inputs'!F41>=40,100,IF('1_Inputs'!F41>=30,80,IF('1_Inputs'!F41>=20,50,IF('1_Inputs'!F41>=10,25,0)))),IF('1_Inputs'!F41>=35,100,IF('1_Inputs'!F41>=25,80,IF('1_Inputs'!F41>=15,50,IF('1_Inputs'!F41>=8,25,0)))))
A12: Balance 1 pie | B12: 0.08 | C12: =IF('1_Inputs'!C42>=60,100,IF('1_Inputs'!C42>=30,80,IF('1_Inputs'!C42>=15,50,IF('1_Inputs'!C42>=5,25,0)))) | D12: =IF('1_Inputs'!D42>=60,100,IF('1_Inputs'!D42>=30,80,IF('1_Inputs'!D42>=15,50,IF('1_Inputs'!D42>=5,25,0)))) | E12: =IF('1_Inputs'!E42>=60,100,IF('1_Inputs'!E42>=30,80,IF('1_Inputs'!E42>=15,50,IF('1_Inputs'!E42>=5,25,0)))) | F12: =IF('1_Inputs'!F42>=60,100,IF('1_Inputs'!F42>=30,80,IF('1_Inputs'!F42>=15,50,IF('1_Inputs'!F42>=5,25,0))))
A13: Plank máx | B13: 0.07 | C13: =IF('1_Inputs'!C43>=180,100,IF('1_Inputs'!C43>=90,80,IF('1_Inputs'!C43>=45,50,IF('1_Inputs'!C43>=20,25,0)))) | D13: =IF('1_Inputs'!D43>=180,100,IF('1_Inputs'!D43>=90,80,IF('1_Inputs'!D43>=45,50,IF('1_Inputs'!D43>=20,25,0)))) | E13: =IF('1_Inputs'!E43>=180,100,IF('1_Inputs'!E43>=90,80,IF('1_Inputs'!E43>=45,50,IF('1_Inputs'!E43>=20,25,0)))) | F13: =IF('1_Inputs'!F43>=180,100,IF('1_Inputs'!F43>=90,80,IF('1_Inputs'!F43>=45,50,IF('1_Inputs'!F43>=20,25,0))))
A14: Recovery HR 2-min | B14: 0.05 | C14: =IF('1_Inputs'!C45>=40,100,IF('1_Inputs'!C45>=25,80,IF('1_Inputs'!C45>=15,50,IF('1_Inputs'!C45>=10,25,0)))) | D14: =IF('1_Inputs'!D45>=40,100,IF('1_Inputs'!D45>=25,80,IF('1_Inputs'!D45>=15,50,IF('1_Inputs'!D45>=10,25,0)))) | E14: =IF('1_Inputs'!E45>=40,100,IF('1_Inputs'!E45>=25,80,IF('1_Inputs'!E45>=15,50,IF('1_Inputs'!E45>=10,25,0)))) | F14: =IF('1_Inputs'!F45>=40,100,IF('1_Inputs'!F45>=25,80,IF('1_Inputs'!F45>=15,50,IF('1_Inputs'!F45>=10,25,0))))
A15: BOLT | B15: 0.05 | C15: =IF('1_Inputs'!C44>=40,100,IF('1_Inputs'!C44>=25,80,IF('1_Inputs'!C44>=15,50,IF('1_Inputs'!C44>=10,25,0)))) | D15: =IF('1_Inputs'!D44>=40,100,IF('1_Inputs'!D44>=25,80,IF('1_Inputs'!D44>=15,50,IF('1_Inputs'!D44>=10,25,0)))) | E15: =IF('1_Inputs'!E44>=40,100,IF('1_Inputs'!E44>=25,80,IF('1_Inputs'!E44>=15,50,IF('1_Inputs'!E44>=10,25,0)))) | F15: =IF('1_Inputs'!F44>=40,100,IF('1_Inputs'!F44>=25,80,IF('1_Inputs'!F44>=15,50,IF('1_Inputs'!F44>=10,25,0))))
A16: Score Fitness (0-100) | C16: =SUMPRODUCT(C7:C15,$B$7:$B$15) | D16: =SUMPRODUCT(D7:D15,$B$7:$B$15) | E16: =SUMPRODUCT(E7:E15,$B$7:$B$15) | F16: =SUMPRODUCT(F7:F15,$B$7:$B$15)
A17: ═══ EDAD FITNESS (ciega) ═══ | C17: =IF(C16>=95,22,IF(C16>=90,28-(C16-90)/5*6,IF(C16>=80,33-(C16-80)/10*5,IF(C16>=70,42-(C16-70)/10*9,IF(C16>=60,50-(C16-60)/10*8,IF(C16>=50,60-(C16-50)/10*10,IF(C16>=40,70-(C16-40)/10*10,IF(C16>=30,80-(C16-30)/10*10,MIN(100,90+(30-C16)/30*10))))))))) | D17: =IF(D16>=95,22,IF(D16>=90,28-(D16-90)/5*6,IF(D16>=80,33-(D16-80)/10*5,IF(D16>=70,42-(D16-70)/10*9,IF(D16>=60,50-(D16-60)/10*8,IF(D16>=50,60-(D16-50)/10*10,IF(D16>=40,70-(D16-40)/10*10,IF(D16>=30,80-(D16-30)/10*10,MIN(100,90+(30-D16)/30*10))))))))) | E17: =IF(E16>=95,22,IF(E16>=90,28-(E16-90)/5*6,IF(E16>=80,33-(E16-80)/10*5,IF(E16>=70,42-(E16-70)/10*9,IF(E16>=60,50-(E16-60)/10*8,IF(E16>=50,60-(E16-50)/10*10,IF(E16>=40,70-(E16-40)/10*10,IF(E16>=30,80-(E16-30)/10*10,MIN(100,90+(30-E16)/30*10))))))))) | F17: =IF(F16>=95,22,IF(F16>=90,28-(F16-90)/5*6,IF(F16>=80,33-(F16-80)/10*5,IF(F16>=70,42-(F16-70)/10*9,IF(F16>=60,50-(F16-60)/10*8,IF(F16>=50,60-(F16-50)/10*10,IF(F16>=40,70-(F16-40)/10*10,IF(F16>=30,80-(F16-30)/10*10,MIN(100,90+(30-F16)/30*10)))))))))

Sheet 5_Area_Cognicion
A1: ÁREA 4 — COGNICIÓN
A3: Curvas Der & Deary 2006 (UK Health & Lifestyle Survey n=7,130). Go/No-Go añadido para inhibición prefrontal.
A5: Test | B5: Peso | C5: H1 | D5: H2 | E5: M1 | F5: M2
A6: Simple RT (Der & Deary 06) | B6: 0.3 | C6: =IF('1_Inputs'!C50<=250,20,IF('1_Inputs'!C50<=270,20+('1_Inputs'!C50-250)/(270-250)*10,IF('1_Inputs'!C50<=290,30+('1_Inputs'!C50-270)/(290-270)*10,IF('1_Inputs'!C50<=320,40+('1_Inputs'!C50-290)/(320-290)*10,IF('1_Inputs'!C50<=360,50+('1_Inputs'!C50-320)/(360-320)*10,IF('1_Inputs'!C50<=410,60+('1_Inputs'!C50-360)/(410-360)*10,IF('1_Inputs'!C50<=470,70+('1_Inputs'!C50-410)/(470-410)*10,MIN(100,80+('1_Inputs'!C50-470)/30*10)))))))) | D6: =IF('1_Inputs'!D50<=250,20,IF('1_Inputs'!D50<=270,20+('1_Inputs'!D50-250)/(270-250)*10,IF('1_Inputs'!D50<=290,30+('1_Inputs'!D50-270)/(290-270)*10,IF('1_Inputs'!D50<=320,40+('1_Inputs'!D50-290)/(320-290)*10,IF('1_Inputs'!D50<=360,50+('1_Inputs'!D50-320)/(360-320)*10,IF('1_Inputs'!D50<=410,60+('1_Inputs'!D50-360)/(410-360)*10,IF('1_Inputs'!D50<=470,70+('1_Inputs'!D50-410)/(470-410)*10,MIN(100,80+('1_Inputs'!D50-470)/30*10)))))))) | E6: =IF('1_Inputs'!E50<=250,20,IF('1_Inputs'!E50<=270,20+('1_Inputs'!E50-250)/(270-250)*10,IF('1_Inputs'!E50<=290,30+('1_Inputs'!E50-270)/(290-270)*10,IF('1_Inputs'!E50<=320,40+('1_Inputs'!E50-290)/(320-290)*10,IF('1_Inputs'!E50<=360,50+('1_Inputs'!E50-320)/(360-320)*10,IF('1_Inputs'!E50<=410,60+('1_Inputs'!E50-360)/(410-360)*10,IF('1_Inputs'!E50<=470,70+('1_Inputs'!E50-410)/(470-410)*10,MIN(100,80+('1_Inputs'!E50-470)/30*10)))))))) | F6: =IF('1_Inputs'!F50<=250,20,IF('1_Inputs'!F50<=270,20+('1_Inputs'!F50-250)/(270-250)*10,IF('1_Inputs'!F50<=290,30+('1_Inputs'!F50-270)/(290-270)*10,IF('1_Inputs'!F50<=320,40+('1_Inputs'!F50-290)/(320-290)*10,IF('1_Inputs'!F50<=360,50+('1_Inputs'!F50-320)/(360-320)*10,IF('1_Inputs'!F50<=410,60+('1_Inputs'!F50-360)/(410-360)*10,IF('1_Inputs'!F50<=470,70+('1_Inputs'!F50-410)/(470-410)*10,MIN(100,80+('1_Inputs'!F50-470)/30*10))))))))
A7: Choice RT (Der & Deary 06) | B7: 0.3 | C7: =IF('1_Inputs'!C51<=440,20,IF('1_Inputs'!C51<=470,20+('1_Inputs'!C51-440)/(470-440)*10,IF('1_Inputs'!C51<=500,30+('1_Inputs'!C51-470)/(500-470)*10,IF('1_Inputs'!C51<=540,40+('1_Inputs'!C51-500)/(540-500)*10,IF('1_Inputs'!C51<=600,50+('1_Inputs'!C51-540)/(600-540)*10,IF('1_Inputs'!C51<=680,60+('1_Inputs'!C51-600)/(680-600)*10,IF('1_Inputs'!C51<=780,70+('1_Inputs'!C51-680)/(780-680)*10,MIN(100,80+('1_Inputs'!C51-780)/50*10)))))))) | D7: =IF('1_Inputs'!D51<=440,20,IF('1_Inputs'!D51<=470,20+('1_Inputs'!D51-440)/(470-440)*10,IF('1_Inputs'!D51<=500,30+('1_Inputs'!D51-470)/(500-470)*10,IF('1_Inputs'!D51<=540,40+('1_Inputs'!D51-500)/(540-500)*10,IF('1_Inputs'!D51<=600,50+('1_Inputs'!D51-540)/(600-540)*10,IF('1_Inputs'!D51<=680,60+('1_Inputs'!D51-600)/(680-600)*10,IF('1_Inputs'!D51<=780,70+('1_Inputs'!D51-680)/(780-680)*10,MIN(100,80+('1_Inputs'!D51-780)/50*10)))))))) | E7: =IF('1_Inputs'!E51<=440,20,IF('1_Inputs'!E51<=470,20+('1_Inputs'!E51-440)/(470-440)*10,IF('1_Inputs'!E51<=500,30+('1_Inputs'!E51-470)/(500-470)*10,IF('1_Inputs'!E51<=540,40+('1_Inputs'!E51-500)/(540-500)*10,IF('1_Inputs'!E51<=600,50+('1_Inputs'!E51-540)/(600-540)*10,IF('1_Inputs'!E51<=680,60+('1_Inputs'!E51-600)/(680-600)*10,IF('1_Inputs'!E51<=780,70+('1_Inputs'!E51-680)/(780-680)*10,MIN(100,80+('1_Inputs'!E51-780)/50*10)))))))) | F7: =IF('1_Inputs'!F51<=440,20,IF('1_Inputs'!F51<=470,20+('1_Inputs'!F51-440)/(470-440)*10,IF('1_Inputs'!F51<=500,30+('1_Inputs'!F51-470)/(500-470)*10,IF('1_Inputs'!F51<=540,40+('1_Inputs'!F51-500)/(540-500)*10,IF('1_Inputs'!F51<=600,50+('1_Inputs'!F51-540)/(600-540)*10,IF('1_Inputs'!F51<=680,60+('1_Inputs'!F51-600)/(680-600)*10,IF('1_Inputs'!F51<=780,70+('1_Inputs'!F51-680)/(780-680)*10,MIN(100,80+('1_Inputs'!F51-780)/50*10))))))))
A8: Go/No-Go (RT + errores) | B8: 0.25 | C8: =(IF('1_Inputs'!C52<=280,20,IF('1_Inputs'!C52<=310,20+('1_Inputs'!C52-280)/(310-280)*10,IF('1_Inputs'!C52<=340,30+('1_Inputs'!C52-310)/(340-310)*10,IF('1_Inputs'!C52<=380,40+('1_Inputs'!C52-340)/(380-340)*10,IF('1_Inputs'!C52<=430,50+('1_Inputs'!C52-380)/(430-380)*10,IF('1_Inputs'!C52<=490,60+('1_Inputs'!C52-430)/(490-430)*10,IF('1_Inputs'!C52<=560,70+('1_Inputs'!C52-490)/(560-490)*10,MIN(100,80+('1_Inputs'!C52-560)/40*10)))))))))+(IF('1_Inputs'!C53<5,0,IF('1_Inputs'!C53<10,2,IF('1_Inputs'!C53<20,5,10)))) | D8: =(IF('1_Inputs'!D52<=280,20,IF('1_Inputs'!D52<=310,20+('1_Inputs'!D52-280)/(310-280)*10,IF('1_Inputs'!D52<=340,30+('1_Inputs'!D52-310)/(340-310)*10,IF('1_Inputs'!D52<=380,40+('1_Inputs'!D52-340)/(380-340)*10,IF('1_Inputs'!D52<=430,50+('1_Inputs'!D52-380)/(430-380)*10,IF('1_Inputs'!D52<=490,60+('1_Inputs'!D52-430)/(490-430)*10,IF('1_Inputs'!D52<=560,70+('1_Inputs'!D52-490)/(560-490)*10,MIN(100,80+('1_Inputs'!D52-560)/40*10)))))))))+(IF('1_Inputs'!D53<5,0,IF('1_Inputs'!D53<10,2,IF('1_Inputs'!D53<20,5,10)))) | E8: =(IF('1_Inputs'!E52<=280,20,IF('1_Inputs'!E52<=310,20+('1_Inputs'!E52-280)/(310-280)*10,IF('1_Inputs'!E52<=340,30+('1_Inputs'!E52-310)/(340-310)*10,IF('1_Inputs'!E52<=380,40+('1_Inputs'!E52-340)/(380-340)*10,IF('1_Inputs'!E52<=430,50+('1_Inputs'!E52-380)/(430-380)*10,IF('1_Inputs'!E52<=490,60+('1_Inputs'!E52-430)/(490-430)*10,IF('1_Inputs'!E52<=560,70+('1_Inputs'!E52-490)/(560-490)*10,MIN(100,80+('1_Inputs'!E52-560)/40*10)))))))))+(IF('1_Inputs'!E53<5,0,IF('1_Inputs'!E53<10,2,IF('1_Inputs'!E53<20,5,10)))) | F8: =(IF('1_Inputs'!F52<=280,20,IF('1_Inputs'!F52<=310,20+('1_Inputs'!F52-280)/(310-280)*10,IF('1_Inputs'!F52<=340,30+('1_Inputs'!F52-310)/(340-310)*10,IF('1_Inputs'!F52<=380,40+('1_Inputs'!F52-340)/(380-340)*10,IF('1_Inputs'!F52<=430,50+('1_Inputs'!F52-380)/(430-380)*10,IF('1_Inputs'!F52<=490,60+('1_Inputs'!F52-430)/(490-430)*10,IF('1_Inputs'!F52<=560,70+('1_Inputs'!F52-490)/(560-490)*10,MIN(100,80+('1_Inputs'!F52-560)/40*10)))))))))+(IF('1_Inputs'!F53<5,0,IF('1_Inputs'!F53<10,2,IF('1_Inputs'!F53<20,5,10))))
A9: Subjetivos (claridad/energía/memoria) | B9: 0.15 | C9: ='1_Inputs'!C5+(7-AVERAGE('1_Inputs'!C54,'1_Inputs'!C55,'1_Inputs'!C56))*5 | D9: ='1_Inputs'!D5+(7-AVERAGE('1_Inputs'!D54,'1_Inputs'!D55,'1_Inputs'!D56))*5 | E9: ='1_Inputs'!E5+(7-AVERAGE('1_Inputs'!E54,'1_Inputs'!E55,'1_Inputs'!E56))*5 | F9: ='1_Inputs'!F5+(7-AVERAGE('1_Inputs'!F54,'1_Inputs'!F55,'1_Inputs'!F56))*5
A10: ═══ EDAD COGNICIÓN (ciega) ═══ | B10: Promedio ponderado de las 4 edades parciales | C10: =SUMPRODUCT(C6:C9,$B$6:$B$9) | D10: =SUMPRODUCT(D6:D9,$B$6:$B$9) | E10: =SUMPRODUCT(E6:E9,$B$6:$B$9) | F10: =SUMPRODUCT(F6:F9,$B$6:$B$9)

Sheet 6_Area_Riesgos
A1: ÁREA 5 — RIESGOS DE PADECIMIENTOS
A3: Sub-bloques: cardio + metabólico + inflamatorio + hormonal + hepatorenal
A5: Param | B5: Peso intra-bloque | C5: H1 score | D5: H2 score | E5: M1 score | F5: M2 score
A6: — SUB-BLOQUE CARDIOVASCULAR (peso intra: 1.0) —
A7: ApoB | B7: 0.2 | C7: =IF('1_Inputs'!C59<=80,100,IF('1_Inputs'!C59<=99,80,IF('1_Inputs'!C59<=110,50,IF('1_Inputs'!C59<=125,25,0)))) | D7: =IF('1_Inputs'!D59<=80,100,IF('1_Inputs'!D59<=99,80,IF('1_Inputs'!D59<=110,50,IF('1_Inputs'!D59<=125,25,0)))) | E7: =IF('1_Inputs'!E59<=80,100,IF('1_Inputs'!E59<=99,80,IF('1_Inputs'!E59<=110,50,IF('1_Inputs'!E59<=125,25,0)))) | F7: =IF('1_Inputs'!F59<=80,100,IF('1_Inputs'!F59<=99,80,IF('1_Inputs'!F59<=110,50,IF('1_Inputs'!F59<=125,25,0))))
A8: LDL | B8: 0.1 | C8: =IF('1_Inputs'!C60<=100,100,IF('1_Inputs'!C60<=130,80,IF('1_Inputs'!C60<=160,50,IF('1_Inputs'!C60<=190,25,0)))) | D8: =IF('1_Inputs'!D60<=100,100,IF('1_Inputs'!D60<=130,80,IF('1_Inputs'!D60<=160,50,IF('1_Inputs'!D60<=190,25,0)))) | E8: =IF('1_Inputs'!E60<=100,100,IF('1_Inputs'!E60<=130,80,IF('1_Inputs'!E60<=160,50,IF('1_Inputs'!E60<=190,25,0)))) | F8: =IF('1_Inputs'!F60<=100,100,IF('1_Inputs'!F60<=130,80,IF('1_Inputs'!F60<=160,50,IF('1_Inputs'!F60<=190,25,0))))
A9: HDL | B9: 0.15 | C9: =IF('1_Inputs'!C61>=60,100,IF('1_Inputs'!C61>=50,80,IF('1_Inputs'!C61>=40,50,IF('1_Inputs'!C61>=30,25,0)))) | D9: =IF('1_Inputs'!D61>=60,100,IF('1_Inputs'!D61>=50,80,IF('1_Inputs'!D61>=40,50,IF('1_Inputs'!D61>=30,25,0)))) | E9: =IF('1_Inputs'!E61>=60,100,IF('1_Inputs'!E61>=50,80,IF('1_Inputs'!E61>=40,50,IF('1_Inputs'!E61>=30,25,0)))) | F9: =IF('1_Inputs'!F61>=60,100,IF('1_Inputs'!F61>=50,80,IF('1_Inputs'!F61>=40,50,IF('1_Inputs'!F61>=30,25,0))))
A10: Triglicéridos | B10: 0.1 | C10: =IF('1_Inputs'!C63<=100,100,IF('1_Inputs'!C63<=150,80,IF('1_Inputs'!C63<=200,50,IF('1_Inputs'!C63<=300,25,0)))) | D10: =IF('1_Inputs'!D63<=100,100,IF('1_Inputs'!D63<=150,80,IF('1_Inputs'!D63<=200,50,IF('1_Inputs'!D63<=300,25,0)))) | E10: =IF('1_Inputs'!E63<=100,100,IF('1_Inputs'!E63<=150,80,IF('1_Inputs'!E63<=200,50,IF('1_Inputs'!E63<=300,25,0)))) | F10: =IF('1_Inputs'!F63<=100,100,IF('1_Inputs'!F63<=150,80,IF('1_Inputs'!F63<=200,50,IF('1_Inputs'!F63<=300,25,0))))
A11: Ratio TG/HDL | B11: 0.15 | C11: =IF(('1_Inputs'!C63/'1_Inputs'!C61)<=2,100,IF(('1_Inputs'!C63/'1_Inputs'!C61)<=3,80,IF(('1_Inputs'!C63/'1_Inputs'!C61)<=4,50,IF(('1_Inputs'!C63/'1_Inputs'!C61)<=6,25,0)))) | D11: =IF(('1_Inputs'!D63/'1_Inputs'!D61)<=2,100,IF(('1_Inputs'!D63/'1_Inputs'!D61)<=3,80,IF(('1_Inputs'!D63/'1_Inputs'!D61)<=4,50,IF(('1_Inputs'!D63/'1_Inputs'!D61)<=6,25,0)))) | E11: =IF(('1_Inputs'!E63/'1_Inputs'!E61)<=2,100,IF(('1_Inputs'!E63/'1_Inputs'!E61)<=3,80,IF(('1_Inputs'!E63/'1_Inputs'!E61)<=4,50,IF(('1_Inputs'!E63/'1_Inputs'!E61)<=6,25,0)))) | F11: =IF(('1_Inputs'!F63/'1_Inputs'!F61)<=2,100,IF(('1_Inputs'!F63/'1_Inputs'!F61)<=3,80,IF(('1_Inputs'!F63/'1_Inputs'!F61)<=4,50,IF(('1_Inputs'!F63/'1_Inputs'!F61)<=6,25,0))))
A12: PA Sistólica | B12: 0.15 | C12: =IF(AND('1_Inputs'!C64>=90,'1_Inputs'!C64<=115),100,IF('1_Inputs'!C64<=120,80,IF('1_Inputs'!C64<=130,50,IF('1_Inputs'!C64<=140,25,0)))) | D12: =IF(AND('1_Inputs'!D64>=90,'1_Inputs'!D64<=115),100,IF('1_Inputs'!D64<=120,80,IF('1_Inputs'!D64<=130,50,IF('1_Inputs'!D64<=140,25,0)))) | E12: =IF(AND('1_Inputs'!E64>=90,'1_Inputs'!E64<=115),100,IF('1_Inputs'!E64<=120,80,IF('1_Inputs'!E64<=130,50,IF('1_Inputs'!E64<=140,25,0)))) | F12: =IF(AND('1_Inputs'!F64>=90,'1_Inputs'!F64<=115),100,IF('1_Inputs'!F64<=120,80,IF('1_Inputs'!F64<=130,50,IF('1_Inputs'!F64<=140,25,0))))
A13: PA Diastólica | B13: 0.1 | C13: =IF(AND('1_Inputs'!C65>=60,'1_Inputs'!C65<=75),100,IF('1_Inputs'!C65<=85,80,IF('1_Inputs'!C65<=90,50,IF('1_Inputs'!C65<=100,25,0)))) | D13: =IF(AND('1_Inputs'!D65>=60,'1_Inputs'!D65<=75),100,IF('1_Inputs'!D65<=85,80,IF('1_Inputs'!D65<=90,50,IF('1_Inputs'!D65<=100,25,0)))) | E13: =IF(AND('1_Inputs'!E65>=60,'1_Inputs'!E65<=75),100,IF('1_Inputs'!E65<=85,80,IF('1_Inputs'!E65<=90,50,IF('1_Inputs'!E65<=100,25,0)))) | F13: =IF(AND('1_Inputs'!F65>=60,'1_Inputs'!F65<=75),100,IF('1_Inputs'!F65<=85,80,IF('1_Inputs'!F65<=90,50,IF('1_Inputs'!F65<=100,25,0))))
A14: Colesterol Total | B14: 0.05 | C14: =IF('1_Inputs'!C62<=200,100,IF('1_Inputs'!C62<=220,80,IF('1_Inputs'!C62<=240,50,IF('1_Inputs'!C62<=280,25,0)))) | D14: =IF('1_Inputs'!D62<=200,100,IF('1_Inputs'!D62<=220,80,IF('1_Inputs'!D62<=240,50,IF('1_Inputs'!D62<=280,25,0)))) | E14: =IF('1_Inputs'!E62<=200,100,IF('1_Inputs'!E62<=220,80,IF('1_Inputs'!E62<=240,50,IF('1_Inputs'!E62<=280,25,0)))) | F14: =IF('1_Inputs'!F62<=200,100,IF('1_Inputs'!F62<=220,80,IF('1_Inputs'!F62<=240,50,IF('1_Inputs'!F62<=280,25,0))))
A15: Score Cardio | C15: =SUMPRODUCT(C7:C14,$B$7:$B$14) | D15: =SUMPRODUCT(D7:D14,$B$7:$B$14) | E15: =SUMPRODUCT(E7:E14,$B$7:$B$14) | F15: =SUMPRODUCT(F7:F14,$B$7:$B$14)
A17: — SUB-BLOQUE METABÓLICO —
A18: HbA1c | B18: 0.35 | C18: =IF('1_Inputs'!C66<=5.5,100,IF('1_Inputs'!C66<=5.6,80,IF('1_Inputs'!C66<=6.0,50,IF('1_Inputs'!C66<=6.5,25,0)))) | D18: =IF('1_Inputs'!D66<=5.5,100,IF('1_Inputs'!D66<=5.6,80,IF('1_Inputs'!D66<=6.0,50,IF('1_Inputs'!D66<=6.5,25,0)))) | E18: =IF('1_Inputs'!E66<=5.5,100,IF('1_Inputs'!E66<=5.6,80,IF('1_Inputs'!E66<=6.0,50,IF('1_Inputs'!E66<=6.5,25,0)))) | F18: =IF('1_Inputs'!F66<=5.5,100,IF('1_Inputs'!F66<=5.6,80,IF('1_Inputs'!F66<=6.0,50,IF('1_Inputs'!F66<=6.5,25,0))))
A19: HOMA-IR | B19: 0.3 | C19: =IF('1_Inputs'!C68<=1,100,IF('1_Inputs'!C68<=1.5,80,IF('1_Inputs'!C68<=2.5,50,IF('1_Inputs'!C68<=4,25,0)))) | D19: =IF('1_Inputs'!D68<=1,100,IF('1_Inputs'!D68<=1.5,80,IF('1_Inputs'!D68<=2.5,50,IF('1_Inputs'!D68<=4,25,0)))) | E19: =IF('1_Inputs'!E68<=1,100,IF('1_Inputs'!E68<=1.5,80,IF('1_Inputs'!E68<=2.5,50,IF('1_Inputs'!E68<=4,25,0)))) | F19: =IF('1_Inputs'!F68<=1,100,IF('1_Inputs'!F68<=1.5,80,IF('1_Inputs'!F68<=2.5,50,IF('1_Inputs'!F68<=4,25,0))))
A20: Glucosa ayuno | B20: 0.2 | C20: =IF('1_Inputs'!C11<=90,100,IF('1_Inputs'!C11<=100,80,IF('1_Inputs'!C11<=110,50,IF('1_Inputs'!C11<=125,25,0)))) | D20: =IF('1_Inputs'!D11<=90,100,IF('1_Inputs'!D11<=100,80,IF('1_Inputs'!D11<=110,50,IF('1_Inputs'!D11<=125,25,0)))) | E20: =IF('1_Inputs'!E11<=90,100,IF('1_Inputs'!E11<=100,80,IF('1_Inputs'!E11<=110,50,IF('1_Inputs'!E11<=125,25,0)))) | F20: =IF('1_Inputs'!F11<=90,100,IF('1_Inputs'!F11<=100,80,IF('1_Inputs'!F11<=110,50,IF('1_Inputs'!F11<=125,25,0))))
A21: Insulina ayuno | B21: 0.15 | C21: =IF('1_Inputs'!C67<=5,100,IF('1_Inputs'!C67<=8,80,IF('1_Inputs'!C67<=12,50,IF('1_Inputs'!C67<=20,25,0)))) | D21: =IF('1_Inputs'!D67<=5,100,IF('1_Inputs'!D67<=8,80,IF('1_Inputs'!D67<=12,50,IF('1_Inputs'!D67<=20,25,0)))) | E21: =IF('1_Inputs'!E67<=5,100,IF('1_Inputs'!E67<=8,80,IF('1_Inputs'!E67<=12,50,IF('1_Inputs'!E67<=20,25,0)))) | F21: =IF('1_Inputs'!F67<=5,100,IF('1_Inputs'!F67<=8,80,IF('1_Inputs'!F67<=12,50,IF('1_Inputs'!F67<=20,25,0))))
A22: Score Metabólico | C22: =SUMPRODUCT(C18:C21,$B$18:$B$21) | D22: =SUMPRODUCT(D18:D21,$B$18:$B$21) | E22: =SUMPRODUCT(E18:E21,$B$18:$B$21) | F22: =SUMPRODUCT(F18:F21,$B$18:$B$21)
A24: — SUB-BLOQUE INFLAMATORIO —
A25: PCR | B25: 0.4 | C25: =IF('1_Inputs'!C12<=0.5,100,IF('1_Inputs'!C12<=1,80,IF('1_Inputs'!C12<=3,50,IF('1_Inputs'!C12<=10,25,0)))) | D25: =IF('1_Inputs'!D12<=0.5,100,IF('1_Inputs'!D12<=1,80,IF('1_Inputs'!D12<=3,50,IF('1_Inputs'!D12<=10,25,0)))) | E25: =IF('1_Inputs'!E12<=0.5,100,IF('1_Inputs'!E12<=1,80,IF('1_Inputs'!E12<=3,50,IF('1_Inputs'!E12<=10,25,0)))) | F25: =IF('1_Inputs'!F12<=0.5,100,IF('1_Inputs'!F12<=1,80,IF('1_Inputs'!F12<=3,50,IF('1_Inputs'!F12<=10,25,0))))
A26: Homocisteína | B26: 0.3 | C26: =IF('1_Inputs'!C22<=8,100,IF('1_Inputs'!C22<=11,80,IF('1_Inputs'!C22<=13,50,IF('1_Inputs'!C22<=15,25,0)))) | D26: =IF('1_Inputs'!D22<=8,100,IF('1_Inputs'!D22<=11,80,IF('1_Inputs'!D22<=13,50,IF('1_Inputs'!D22<=15,25,0)))) | E26: =IF('1_Inputs'!E22<=8,100,IF('1_Inputs'!E22<=11,80,IF('1_Inputs'!E22<=13,50,IF('1_Inputs'!E22<=15,25,0)))) | F26: =IF('1_Inputs'!F22<=8,100,IF('1_Inputs'!F22<=11,80,IF('1_Inputs'!F22<=13,50,IF('1_Inputs'!F22<=15,25,0))))
A27: NLR (Neutróf/Linfo) | B27: 0.3 | C27: =IF('1_Inputs'!C71<=1.5,100,IF('1_Inputs'!C71<=2,80,IF('1_Inputs'!C71<=2.5,50,IF('1_Inputs'!C71<=3.5,25,0)))) | D27: =IF('1_Inputs'!D71<=1.5,100,IF('1_Inputs'!D71<=2,80,IF('1_Inputs'!D71<=2.5,50,IF('1_Inputs'!D71<=3.5,25,0)))) | E27: =IF('1_Inputs'!E71<=1.5,100,IF('1_Inputs'!E71<=2,80,IF('1_Inputs'!E71<=2.5,50,IF('1_Inputs'!E71<=3.5,25,0)))) | F27: =IF('1_Inputs'!F71<=1.5,100,IF('1_Inputs'!F71<=2,80,IF('1_Inputs'!F71<=2.5,50,IF('1_Inputs'!F71<=3.5,25,0))))
A28: Score Inflamatorio | C28: =SUMPRODUCT(C25:C27,$B$25:$B$27) | D28: =SUMPRODUCT(D25:D27,$B$25:$B$27) | E28: =SUMPRODUCT(E25:E27,$B$25:$B$27) | F28: =SUMPRODUCT(F25:F27,$B$25:$B$27)
A30: — SUB-BLOQUE HORMONAL —
A31: Testo (H) / Estradiol (M) | B31: 0.4 | C31: =IF('1_Inputs'!C6=1,IF(AND('1_Inputs'!C74>=4,'1_Inputs'!C74<=8),100,IF(AND('1_Inputs'!C74>=3,'1_Inputs'!C74<4),80,IF(AND('1_Inputs'!C74>=8,'1_Inputs'!C74<=12),80,IF('1_Inputs'!C74<3,25,50)))),IF(AND('1_Inputs'!C74>=30,'1_Inputs'!C74<=200),100,IF(AND('1_Inputs'!C74>=200,'1_Inputs'!C74<=400),80,IF('1_Inputs'!C74<30,25,50)))) | D31: =IF('1_Inputs'!D6=1,IF(AND('1_Inputs'!D74>=4,'1_Inputs'!D74<=8),100,IF(AND('1_Inputs'!D74>=3,'1_Inputs'!D74<4),80,IF(AND('1_Inputs'!D74>=8,'1_Inputs'!D74<=12),80,IF('1_Inputs'!D74<3,25,50)))),IF(AND('1_Inputs'!D74>=30,'1_Inputs'!D74<=200),100,IF(AND('1_Inputs'!D74>=200,'1_Inputs'!D74<=400),80,IF('1_Inputs'!D74<30,25,50)))) | E31: =IF('1_Inputs'!E6=1,IF(AND('1_Inputs'!E74>=4,'1_Inputs'!E74<=8),100,IF(AND('1_Inputs'!E74>=3,'1_Inputs'!E74<4),80,IF(AND('1_Inputs'!E74>=8,'1_Inputs'!E74<=12),80,IF('1_Inputs'!E74<3,25,50)))),IF(AND('1_Inputs'!E74>=30,'1_Inputs'!E74<=200),100,IF(AND('1_Inputs'!E74>=200,'1_Inputs'!E74<=400),80,IF('1_Inputs'!E74<30,25,50)))) | F31: =IF('1_Inputs'!F6=1,IF(AND('1_Inputs'!F74>=4,'1_Inputs'!F74<=8),100,IF(AND('1_Inputs'!F74>=3,'1_Inputs'!F74<4),80,IF(AND('1_Inputs'!F74>=8,'1_Inputs'!F74<=12),80,IF('1_Inputs'!F74<3,25,50)))),IF(AND('1_Inputs'!F74>=30,'1_Inputs'!F74<=200),100,IF(AND('1_Inputs'!F74>=200,'1_Inputs'!F74<=400),80,IF('1_Inputs'!F74<30,25,50))))
A32: TSH | B32: 0.25 | C32: =IF(AND('1_Inputs'!C24>=1,'1_Inputs'!C24<=2.5),100,IF(AND('1_Inputs'!C24>=0.5,'1_Inputs'!C24<=3),80,IF(AND('1_Inputs'!C24>0.3,'1_Inputs'!C24<=4),50,IF('1_Inputs'!C24<=5,25,0)))) | D32: =IF(AND('1_Inputs'!D24>=1,'1_Inputs'!D24<=2.5),100,IF(AND('1_Inputs'!D24>=0.5,'1_Inputs'!D24<=3),80,IF(AND('1_Inputs'!D24>0.3,'1_Inputs'!D24<=4),50,IF('1_Inputs'!D24<=5,25,0)))) | E32: =IF(AND('1_Inputs'!E24>=1,'1_Inputs'!E24<=2.5),100,IF(AND('1_Inputs'!E24>=0.5,'1_Inputs'!E24<=3),80,IF(AND('1_Inputs'!E24>0.3,'1_Inputs'!E24<=4),50,IF('1_Inputs'!E24<=5,25,0)))) | F32: =IF(AND('1_Inputs'!F24>=1,'1_Inputs'!F24<=2.5),100,IF(AND('1_Inputs'!F24>=0.5,'1_Inputs'!F24<=3),80,IF(AND('1_Inputs'!F24>0.3,'1_Inputs'!F24<=4),50,IF('1_Inputs'!F24<=5,25,0))))
A33: Cortisol matutino | B33: 0.25 | C33: =IF(AND('1_Inputs'!C25>=6,'1_Inputs'!C25<=15),100,IF('1_Inputs'!C25<=18,80,IF('1_Inputs'!C25<=22,50,25))) | D33: =IF(AND('1_Inputs'!D25>=6,'1_Inputs'!D25<=15),100,IF('1_Inputs'!D25<=18,80,IF('1_Inputs'!D25<=22,50,25))) | E33: =IF(AND('1_Inputs'!E25>=6,'1_Inputs'!E25<=15),100,IF('1_Inputs'!E25<=18,80,IF('1_Inputs'!E25<=22,50,25))) | F33: =IF(AND('1_Inputs'!F25>=6,'1_Inputs'!F25<=15),100,IF('1_Inputs'!F25<=18,80,IF('1_Inputs'!F25<=22,50,25)))
A34: Vitamina D | B34: 0.1 | C34: =IF(AND('1_Inputs'!C20>=30,'1_Inputs'!C20<=70),100,IF('1_Inputs'!C20>=20,50,25)) | D34: =IF(AND('1_Inputs'!D20>=30,'1_Inputs'!D20<=70),100,IF('1_Inputs'!D20>=20,50,25)) | E34: =IF(AND('1_Inputs'!E20>=30,'1_Inputs'!E20<=70),100,IF('1_Inputs'!E20>=20,50,25)) | F34: =IF(AND('1_Inputs'!F20>=30,'1_Inputs'!F20<=70),100,IF('1_Inputs'!F20>=20,50,25))
A35: Score Hormonal | C35: =SUMPRODUCT(C31:C34,$B$31:$B$34) | D35: =SUMPRODUCT(D31:D34,$B$31:$B$34) | E35: =SUMPRODUCT(E31:E34,$B$31:$B$34) | F35: =SUMPRODUCT(F31:F34,$B$31:$B$34)
A37: — SUB-BLOQUE HEPATO-RENAL —
A38: AST | B38: 0.2 | C38: =IF('1_Inputs'!C75<=25,100,IF('1_Inputs'!C75<=35,80,IF('1_Inputs'!C75<=45,50,IF('1_Inputs'!C75<=60,25,0)))) | D38: =IF('1_Inputs'!D75<=25,100,IF('1_Inputs'!D75<=35,80,IF('1_Inputs'!D75<=45,50,IF('1_Inputs'!D75<=60,25,0)))) | E38: =IF('1_Inputs'!E75<=25,100,IF('1_Inputs'!E75<=35,80,IF('1_Inputs'!E75<=45,50,IF('1_Inputs'!E75<=60,25,0)))) | F38: =IF('1_Inputs'!F75<=25,100,IF('1_Inputs'!F75<=35,80,IF('1_Inputs'!F75<=45,50,IF('1_Inputs'!F75<=60,25,0))))
A39: ALT | B39: 0.2 | C39: =IF('1_Inputs'!C76<=25,100,IF('1_Inputs'!C76<=35,80,IF('1_Inputs'!C76<=45,50,IF('1_Inputs'!C76<=60,25,0)))) | D39: =IF('1_Inputs'!D76<=25,100,IF('1_Inputs'!D76<=35,80,IF('1_Inputs'!D76<=45,50,IF('1_Inputs'!D76<=60,25,0)))) | E39: =IF('1_Inputs'!E76<=25,100,IF('1_Inputs'!E76<=35,80,IF('1_Inputs'!E76<=45,50,IF('1_Inputs'!E76<=60,25,0)))) | F39: =IF('1_Inputs'!F76<=25,100,IF('1_Inputs'!F76<=35,80,IF('1_Inputs'!F76<=45,50,IF('1_Inputs'!F76<=60,25,0))))
A40: GGT | B40: 0.2 | C40: =IF('1_Inputs'!C77<=25,100,IF('1_Inputs'!C77<=35,80,IF('1_Inputs'!C77<=50,50,IF('1_Inputs'!C77<=70,25,0)))) | D40: =IF('1_Inputs'!D77<=25,100,IF('1_Inputs'!D77<=35,80,IF('1_Inputs'!D77<=50,50,IF('1_Inputs'!D77<=70,25,0)))) | E40: =IF('1_Inputs'!E77<=25,100,IF('1_Inputs'!E77<=35,80,IF('1_Inputs'!E77<=50,50,IF('1_Inputs'!E77<=70,25,0)))) | F40: =IF('1_Inputs'!F77<=25,100,IF('1_Inputs'!F77<=35,80,IF('1_Inputs'!F77<=50,50,IF('1_Inputs'!F77<=70,25,0))))
A41: BUN | B41: 0.2 | C41: =IF(AND('1_Inputs'!C78>=8,'1_Inputs'!C78<=20),100,IF('1_Inputs'!C78<=25,80,IF('1_Inputs'!C78<=30,50,IF('1_Inputs'!C78<=40,25,0)))) | D41: =IF(AND('1_Inputs'!D78>=8,'1_Inputs'!D78<=20),100,IF('1_Inputs'!D78<=25,80,IF('1_Inputs'!D78<=30,50,IF('1_Inputs'!D78<=40,25,0)))) | E41: =IF(AND('1_Inputs'!E78>=8,'1_Inputs'!E78<=20),100,IF('1_Inputs'!E78<=25,80,IF('1_Inputs'!E78<=30,50,IF('1_Inputs'!E78<=40,25,0)))) | F41: =IF(AND('1_Inputs'!F78>=8,'1_Inputs'!F78<=20),100,IF('1_Inputs'!F78<=25,80,IF('1_Inputs'!F78<=30,50,IF('1_Inputs'!F78<=40,25,0))))
A42: Creatinina | B42: 0.2 | C42: =IF('1_Inputs'!C6=1,IF(AND('1_Inputs'!C10>=0.6,'1_Inputs'!C10<=1.2),100,IF('1_Inputs'!C10<=1.4,80,IF('1_Inputs'!C10<=1.6,50,IF('1_Inputs'!C10<=2,25,0)))),IF(AND('1_Inputs'!C10>=0.5,'1_Inputs'!C10<=1.1),100,IF('1_Inputs'!C10<=1.3,80,IF('1_Inputs'!C10<=1.5,50,IF('1_Inputs'!C10<=1.8,25,0))))) | D42: =IF('1_Inputs'!D6=1,IF(AND('1_Inputs'!D10>=0.6,'1_Inputs'!D10<=1.2),100,IF('1_Inputs'!D10<=1.4,80,IF('1_Inputs'!D10<=1.6,50,IF('1_Inputs'!D10<=2,25,0)))),IF(AND('1_Inputs'!D10>=0.5,'1_Inputs'!D10<=1.1),100,IF('1_Inputs'!D10<=1.3,80,IF('1_Inputs'!D10<=1.5,50,IF('1_Inputs'!D10<=1.8,25,0))))) | E42: =IF('1_Inputs'!E6=1,IF(AND('1_Inputs'!E10>=0.6,'1_Inputs'!E10<=1.2),100,IF('1_Inputs'!E10<=1.4,80,IF('1_Inputs'!E10<=1.6,50,IF('1_Inputs'!E10<=2,25,0)))),IF(AND('1_Inputs'!E10>=0.5,'1_Inputs'!E10<=1.1),100,IF('1_Inputs'!E10<=1.3,80,IF('1_Inputs'!E10<=1.5,50,IF('1_Inputs'!E10<=1.8,25,0))))) | F42: =IF('1_Inputs'!F6=1,IF(AND('1_Inputs'!F10>=0.6,'1_Inputs'!F10<=1.2),100,IF('1_Inputs'!F10<=1.4,80,IF('1_Inputs'!F10<=1.6,50,IF('1_Inputs'!F10<=2,25,0)))),IF(AND('1_Inputs'!F10>=0.5,'1_Inputs'!F10<=1.1),100,IF('1_Inputs'!F10<=1.3,80,IF('1_Inputs'!F10<=1.5,50,IF('1_Inputs'!F10<=1.8,25,0)))))
A43: Score Hepato-Renal | C43: =SUMPRODUCT(C38:C42,$B$38:$B$42) | D43: =SUMPRODUCT(D38:D42,$B$38:$B$42) | E43: =SUMPRODUCT(E38:E42,$B$38:$B$42) | F43: =SUMPRODUCT(F38:F42,$B$38:$B$42)
A45: SCORE RIESGOS INTEGRADO | B45: Pesos sub-bloques
A46: Cardio | B46: 0.3 | C46: =C15 | D46: =D15 | E46: =E15 | F46: =F15
A47: Metabólico | B47: 0.25 | C47: =C22 | D47: =D22 | E47: =E22 | F47: =F22
...

Sheet 7_Habitos_Modulador
A1: HÁBITOS — Modulador transversal de las 5 áreas
A3: Score Hábitos 0-100 → factor multiplicador aplicado a la Edad ATP integral.
A4: Score ≥80 → ×0.95 (bonificación) · 60-79 → ×1.00 (neutro) · 40-59 → ×1.05 · <40 → ×1.10
A6: Hábito | B6: Peso | C6: H1 score | D6: H2 score | E6: M1 score | F6: M2 score
A7: Ayuno IF | B7: 0.1 | C7: =IF('1_Inputs'!C83<12,0,IF('1_Inputs'!C83<14,25,IF('1_Inputs'!C83<16,50,IF('1_Inputs'!C83<20,100,IF('1_Inputs'!C83<23,80,50))))) | D7: =IF('1_Inputs'!D83<12,0,IF('1_Inputs'!D83<14,25,IF('1_Inputs'!D83<16,50,IF('1_Inputs'!D83<20,100,IF('1_Inputs'!D83<23,80,50))))) | E7: =IF('1_Inputs'!E83<12,0,IF('1_Inputs'!E83<14,25,IF('1_Inputs'!E83<16,50,IF('1_Inputs'!E83<20,100,IF('1_Inputs'!E83<23,80,50))))) | F7: =IF('1_Inputs'!F83<12,0,IF('1_Inputs'!F83<14,25,IF('1_Inputs'!F83<16,50,IF('1_Inputs'!F83<20,100,IF('1_Inputs'!F83<23,80,50)))))
A8: Ejercicio | B8: 0.2 | C8: =IF('1_Inputs'!C84<2,0,IF('1_Inputs'!C84<4,25,IF('1_Inputs'!C84<7,50,IF('1_Inputs'!C84<10,80,IF('1_Inputs'!C84<25,100,80))))) | D8: =IF('1_Inputs'!D84<2,0,IF('1_Inputs'!D84<4,25,IF('1_Inputs'!D84<7,50,IF('1_Inputs'!D84<10,80,IF('1_Inputs'!D84<25,100,80))))) | E8: =IF('1_Inputs'!E84<2,0,IF('1_Inputs'!E84<4,25,IF('1_Inputs'!E84<7,50,IF('1_Inputs'!E84<10,80,IF('1_Inputs'!E84<25,100,80))))) | F8: =IF('1_Inputs'!F84<2,0,IF('1_Inputs'!F84<4,25,IF('1_Inputs'!F84<7,50,IF('1_Inputs'!F84<10,80,IF('1_Inputs'!F84<25,100,80)))))
A9: Pasos diarios | B9: 0.1 | C9: =IF('1_Inputs'!C85<5000,0,IF('1_Inputs'!C85<6500,25,IF('1_Inputs'!C85<7800,50,IF('1_Inputs'!C85<15000,100,IF('1_Inputs'!C85<25000,80,50))))) | D9: =IF('1_Inputs'!D85<5000,0,IF('1_Inputs'!D85<6500,25,IF('1_Inputs'!D85<7800,50,IF('1_Inputs'!D85<15000,100,IF('1_Inputs'!D85<25000,80,50))))) | E9: =IF('1_Inputs'!E85<5000,0,IF('1_Inputs'!E85<6500,25,IF('1_Inputs'!E85<7800,50,IF('1_Inputs'!E85<15000,100,IF('1_Inputs'!E85<25000,80,50))))) | F9: =IF('1_Inputs'!F85<5000,0,IF('1_Inputs'!F85<6500,25,IF('1_Inputs'!F85<7800,50,IF('1_Inputs'!F85<15000,100,IF('1_Inputs'!F85<25000,80,50)))))
A10: Tabaquismo | B10: 0.15 | C10: =IF('1_Inputs'!C86=0,100,IF('1_Inputs'!C86<=5,25,0)) | D10: =IF('1_Inputs'!D86=0,100,IF('1_Inputs'!D86<=5,25,0)) | E10: =IF('1_Inputs'!E86=0,100,IF('1_Inputs'!E86<=5,25,0)) | F10: =IF('1_Inputs'!F86=0,100,IF('1_Inputs'!F86<=5,25,0))
A11: Alcohol mensual | B11: 0.1 | C11: =IF('1_Inputs'!C87<=4,100,IF('1_Inputs'!C87<=6,80,IF('1_Inputs'!C87<=10,50,IF('1_Inputs'!C87<=16,25,0)))) | D11: =IF('1_Inputs'!D87<=4,100,IF('1_Inputs'!D87<=6,80,IF('1_Inputs'!D87<=10,50,IF('1_Inputs'!D87<=16,25,0)))) | E11: =IF('1_Inputs'!E87<=4,100,IF('1_Inputs'!E87<=6,80,IF('1_Inputs'!E87<=10,50,IF('1_Inputs'!E87<=16,25,0)))) | F11: =IF('1_Inputs'!F87<=4,100,IF('1_Inputs'!F87<=6,80,IF('1_Inputs'!F87<=10,50,IF('1_Inputs'!F87<=16,25,0))))
A12: Sueño duración | B12: 0.2 | C12: =IF('1_Inputs'!C88<6,0,IF('1_Inputs'!C88<7,50,IF('1_Inputs'!C88<7.5,80,IF('1_Inputs'!C88<=8.5,100,IF('1_Inputs'!C88<=9.5,80,50))))) | D12: =IF('1_Inputs'!D88<6,0,IF('1_Inputs'!D88<7,50,IF('1_Inputs'!D88<7.5,80,IF('1_Inputs'!D88<=8.5,100,IF('1_Inputs'!D88<=9.5,80,50))))) | E12: =IF('1_Inputs'!E88<6,0,IF('1_Inputs'!E88<7,50,IF('1_Inputs'!E88<7.5,80,IF('1_Inputs'!E88<=8.5,100,IF('1_Inputs'!E88<=9.5,80,50))))) | F12: =IF('1_Inputs'!F88<6,0,IF('1_Inputs'!F88<7,50,IF('1_Inputs'!F88<7.5,80,IF('1_Inputs'!F88<=8.5,100,IF('1_Inputs'!F88<=9.5,80,50)))))
A13: Consistencia sueño | B13: 0.15 | C13: =IF('1_Inputs'!C89<=45,100,IF('1_Inputs'!C89<=75,80,IF('1_Inputs'!C89<=90,50,25))) | D13: =IF('1_Inputs'!D89<=45,100,IF('1_Inputs'!D89<=75,80,IF('1_Inputs'!D89<=90,50,25))) | E13: =IF('1_Inputs'!E89<=45,100,IF('1_Inputs'!E89<=75,80,IF('1_Inputs'!E89<=90,50,25))) | F13: =IF('1_Inputs'!F89<=45,100,IF('1_Inputs'!F89<=75,80,IF('1_Inputs'!F89<=90,50,25)))
A14: Score Hábitos (0-100) | C14: =SUMPRODUCT(C7:C13,$B$7:$B$13) | D14: =SUMPRODUCT(D7:D13,$B$7:$B$13) | E14: =SUMPRODUCT(E7:E13,$B$7:$B$13) | F14: =SUMPRODUCT(F7:F13,$B$7:$B$13)
A15: Factor modulador | B15: Score≥80→0.95, 60-79→1.0, 40-59→1.05, <40→1.10 | C15: =IF(C14>=80,0.95,IF(C14>=60,1.0,IF(C14>=40,1.05,1.10))) | D15: =IF(D14>=80,0.95,IF(D14>=60,1.0,IF(D14>=40,1.05,1.10))) | E15: =IF(E14>=80,0.95,IF(E14>=60,1.0,IF(E14>=40,1.05,1.10))) | F15: =IF(F14>=80,0.95,IF(F14>=60,1.0,IF(F14>=40,1.05,1.10)))

Sheet 8_MOTOR_Resultado
A1: MOTOR — EDAD ATP INTEGRAL
A3: ARQUITECTURA: 5 áreas ciegas → anclaje a cronológica → ponderación → modulador hábitos → cap
A4: Factor anclaje POR ÁREA (0_README B25-B29). Confiabilidad alta = más cerca de 0.75
A6: Área | B6: Peso | C6: H1 | D6: H2 Enrique | E6: M1 | F6: M2
A7: Labs (PhenoAge + modifs) | B7: ='0_README'!$B$19 | C7: ='2_Area_Labs'!C44 | D7: ='2_Area_Labs'!D44 | E7: ='2_Area_Labs'!E44 | F7: ='2_Area_Labs'!F44
A8: Composición corporal | B8: ='0_README'!$B$20 | C8: ='3_Area_Composicion'!C13 | D8: ='3_Area_Composicion'!D13 | E8: ='3_Area_Composicion'!E13 | F8: ='3_Area_Composicion'!F13
A9: Fitness / Capacidad física | B9: ='0_README'!$B$21 | C9: ='4_Area_Fitness'!C17 | D9: ='4_Area_Fitness'!D17 | E9: ='4_Area_Fitness'!E17 | F9: ='4_Area_Fitness'!F17
A10: Cognición | B10: ='0_README'!$B$22 | C10: ='5_Area_Cognicion'!C10 | D10: ='5_Area_Cognicion'!D10 | E10: ='5_Area_Cognicion'!E10 | F10: ='5_Area_Cognicion'!F10
A11: Riesgos de padecimientos | B11: ='0_README'!$B$23 | C11: ='6_Area_Riesgos'!C52 | D11: ='6_Area_Riesgos'!D52 | E11: ='6_Area_Riesgos'!E52 | F11: ='6_Area_Riesgos'!F52
A13: Edad cronológica | C13: ='1_Inputs'!C5 | D13: ='1_Inputs'!D5 | E13: ='1_Inputs'!E5 | F13: ='1_Inputs'!F5
A15: ═ EDADES AJUSTADAS (anclaje a cronológica) ═ | B15: edad_aj = cron + (edad_area - cron) × factor_anclaje
A16: Labs ajustada | C16: =C13+(C7-C13)*'0_README'!$B$25 | D16: =D13+(D7-D13)*'0_README'!$B$25 | E16: =E13+(E7-E13)*'0_README'!$B$25 | F16: =F13+(F7-F13)*'0_README'!$B$25
A17: Composición ajustada | C17: =C13+(C8-C13)*'0_README'!$B$26 | D17: =D13+(D8-D13)*'0_README'!$B$26 | E17: =E13+(E8-E13)*'0_README'!$B$26 | F17: =F13+(F8-F13)*'0_README'!$B$26
A18: Fitness ajustada | C18: =C13+(C9-C13)*'0_README'!$B$27 | D18: =D13+(D9-D13)*'0_README'!$B$27 | E18: =E13+(E9-E13)*'0_README'!$B$27 | F18: =F13+(F9-F13)*'0_README'!$B$27
A19: Cognición ajustada | C19: =C13+(C10-C13)*'0_README'!$B$28 | D19: =D13+(D10-D13)*'0_README'!$B$28 | E19: =E13+(E10-E13)*'0_README'!$B$28 | F19: =F13+(F10-F13)*'0_README'!$B$28
A20: Riesgos ajustada | C20: =C13+(C11-C13)*'0_README'!$B$29 | D20: =D13+(D11-D13)*'0_README'!$B$29 | E20: =E13+(E11-E13)*'0_README'!$B$29 | F20: =F13+(F11-F13)*'0_README'!$B$29
A22: ═ EDAD ATP PRE-MODULADOR ═ | B22: Σ(edad_ajustada_i × peso_i) | C22: =C16*'0_README'!$B$19+C17*'0_README'!$B$20+C18*'0_README'!$B$21+C19*'0_README'!$B$22+C20*'0_README'!$B$23 | D22: =D16*'0_README'!$B$19+D17*'0_README'!$B$20+D18*'0_README'!$B$21+D19*'0_README'!$B$22+D20*'0_README'!$B$23 | E22: =E16*'0_README'!$B$19+E17*'0_README'!$B$20+E18*'0_README'!$B$21+E19*'0_README'!$B$22+E20*'0_README'!$B$23 | F22: =F16*'0_README'!$B$19+F17*'0_README'!$B$20+F18*'0_README'!$B$21+F19*'0_README'!$B$22+F20*'0_README'!$B$23
A24: Factor modulador Hábitos | C24: ='7_Habitos_Modulador'!C15 | D24: ='7_Habitos_Modulador'!D15 | E24: ='7_Habitos_Modulador'!E15 | F24: ='7_Habitos_Modulador'!F15
A25: Edad × Modulador hábitos | C25: =C22*C24 | D25: =D22*D24 | E25: =E22*E24 | F25: =F22*F24
A26: ═══ EDAD ATP INTEGRAL (FINAL) ═══ | B26: MAX(CAP_MIN, MIN(CAP_MAX, edad)) | C26: =MAX('0_README'!$B$17,MIN('0_README'!$B$18,C25)) | D26: =MAX('0_README'!$B$17,MIN('0_README'!$B$18,D25)) | E26: =MAX('0_README'!$B$17,MIN('0_README'!$B$18,E25)) | F26: =MAX('0_README'!$B$17,MIN('0_README'!$B$18,F25))
A28: Δ años (cron − Edad ATP) | B28: Positivo = más joven biológicamente | C28: =C13-C26 | D28: =D13-D26 | E28: =E13-E26 | F28: =F13-F26
A30: VALIDACIÓN ESPERADA (vs intuición clínica)
A31: H1 (cron 50) | B31: ~50-55 años (perfil sano-medio)
A32: H2 Enrique (cron 35) | B32: ~22-28 años (atleta GWR)
A33: M1 mujer joven (cron 28) | B33: ~22-26 años (atleta optimizada)
A34: M2 mujer mayor (cron 65) | B34: ~65-72 años (sedentaria, DM2)
A36: NOTAS
A37: • Factor de anclaje en 0_README cell B15 (default 0.5). Ajustable.
A38: • Pesos por área en 0_README B19-B23. Suman 1.0.
A39: • Caps absolutos 20-100 en 0_README B16-B17.
A40: • Cada edad parcial es CIEGA (no usa cronológica). El anclaje se aplica AQUÍ.
A41: • Si una edad parcial es absurda (ej. Labs=10), el anclaje la trae a algo razonable.
A42: • Modulador Hábitos puede ajustar ±5% (0.95 a 1.10) el resultado.
